Workbook

Sheet Groups
A1: Group | B1: Pot | C1: Team | D1: Confederation
A2: A | B2: 1 | C2: Mexico | D2: CONCACAF (host)
A3: A | B3: 2 | C3: South Korea | D3: AFC
A4: A | B4: 3 | C4: South Africa | D4: CAF
A5: A | B5: 4 | C5: Czechia | D5: UEFA
A6: B | B6: 1 | C6: Canada | D6: CONCACAF (host)
A7: B | B7: 2 | C7: Switzerland | D7: UEFA
A8: B | B8: 3 | C8: Qatar | D8: AFC
A9: B | B9: 4 | C9: Bosnia & Herzegovina | D9: UEFA
A10: C | B10: 1 | C10: Brazil | D10: CONMEBOL
A11: C | B11: 2 | C11: Morocco | D11: CAF
A12: C | B12: 3 | C12: Scotland | D12: UEFA
A13: C | B13: 4 | C13: Haiti | D13: CONCACAF
... A49: L | B49: 4 | C49: Ghana | D49: CAF

Sheet Group Matches
A1: GROUP STAGE — enter predicted (ex ante) and actual (ex post) scores in the yellow cells
A2: # | B2: Date | C2: Grp | D2: Team 1 | E2: Team 2 | F2: Ante T1 | G2: Ante T2 | H2: Ante Winner | I2: Ante Loser | J2: Post T1 | K2: Post T2 | L2: Post Winner | M2: Post Loser | N2: T1 err | O2: T2 err | P2: Outcome hit
A3: 1 | B3: Jun 11 | C3: A | D3: Mexico | E3: South Africa | F3: 1 | G3: 0 | H3: =IF(AND(ISNUMBER(F3),ISNUMBER(G3)),IF(F3>G3,D3,IF(G3>F3,E3,"Draw")),"") -> Mexico | I3: =IF(AND(ISNUMBER(F3),ISNUMBER(G3)),IF(F3>G3,E3,IF(G3>F3,D3,"Draw")),"") -> South Africa | J3: 2 | K3: 0 | L3: =IF(AND(ISNUMBER(J3),ISNUMBER(K3)),IF(J3>K3,D3,IF(K3>J3,E3,"Draw")),"") -> Mexico | M3: =IF(AND(ISNUMBER(J3),ISNUMBER(K3)),IF(J3>K3,E3,IF(K3>J3,D3,"Draw")),"") -> South Africa | N3: =IF(AND(ISNUMBER(J3),ISNUMBER(F3)),J3-F3,"") -> 1 | O3: =IF(AND(ISNUMBER(K3),ISNUMBER(G3)),K3-G3,"") -> 0 | P3: =IF(OR(H3="",L3=""),"",IF(H3=L3,1,0)) -> 1
A4: 2 | B4: Jun 11 | C4: A | D4: South Korea | E4: Czechia | F4: 1 | G4: 0 | H4: =IF(AND(ISNUMBER(F4),ISNUMBER(G4)),IF(F4>G4,D4,IF(G4>F4,E4,"Draw")),"") -> South Korea | I4: =IF(AND(ISNUMBER(F4),ISNUMBER(G4)),IF(F4>G4,E4,IF(G4>F4,D4,"Draw")),"") -> Czechia | J4: 2 | K4: 1 | L4: =IF(AND(ISNUMBER(J4),ISNUMBER(K4)),IF(J4>K4,D4,IF(K4>J4,E4,"Draw")),"") -> South Korea | M4: =IF(AND(ISNUMBER(J4),ISNUMBER(K4)),IF(J4>K4,E4,IF(K4>J4,D4,"Draw")),"") -> Czechia | N4: =IF(AND(ISNUMBER(J4),ISNUMBER(F4)),J4-F4,"") -> 1 | O4: =IF(AND(ISNUMBER(K4),ISNUMBER(G4)),K4-G4,"") -> 1 | P4: =IF(OR(H4="",L4=""),"",IF(H4=L4,1,0)) -> 1
A5: 3 | B5: Jun 12 | C5: B | D5: Canada | E5: Bosnia & Herzegovina | F5: 0 | G5: 1 | H5: =IF(AND(ISNUMBER(F5),ISNUMBER(G5)),IF(F5>G5,D5,IF(G5>F5,E5,"Draw")),"") -> Bosnia & Herzegovina | I5: =IF(AND(ISNUMBER(F5),ISNUMBER(G5)),IF(F5>G5,E5,IF(G5>F5,D5,"Draw")),"") -> Canada | J5: 1 | K5: 1 | L5: =IF(AND(ISNUMBER(J5),ISNUMBER(K5)),IF(J5>K5,D5,IF(K5>J5,E5,"Draw")),"") -> Draw | M5: =IF(AND(ISNUMBER(J5),ISNUMBER(K5)),IF(J5>K5,E5,IF(K5>J5,D5,"Draw")),"") -> Draw | N5: =IF(AND(ISNUMBER(J5),ISNUMBER(F5)),J5-F5,"") -> 1 | O5: =IF(AND(ISNUMBER(K5),ISNUMBER(G5)),K5-G5,"") -> 0 | P5: =IF(OR(H5="",L5=""),"",IF(H5=L5,1,0)) -> 0
A6: 4 | B6: Jun 12 | C6: D | D6: United States | E6: Paraguay | F6: 2 | G6: 1 | H6: =IF(AND(ISNUMBER(F6),ISNUMBER(G6)),IF(F6>G6,D6,IF(G6>F6,E6,"Draw")),"") -> United States | I6: =IF(AND(ISNUMBER(F6),ISNUMBER(G6)),IF(F6>G6,E6,IF(G6>F6,D6,"Draw")),"") -> Paraguay | J6: 4 | K6: 1 | L6: =IF(AND(ISNUMBER(J6),ISNUMBER(K6)),IF(J6>K6,D6,IF(K6>J6,E6,"Draw")),"") -> United States | M6: =IF(AND(ISNUMBER(J6),ISNUMBER(K6)),IF(J6>K6,E6,IF(K6>J6,D6,"Draw")),"") -> Paraguay | N6: =IF(AND(ISNUMBER(J6),ISNUMBER(F6)),J6-F6,"") -> 2 | O6: =IF(AND(ISNUMBER(K6),ISNUMBER(G6)),K6-G6,"") -> 0 | P6: =IF(OR(H6="",L6=""),"",IF(H6=L6,1,0)) -> 1
A7: 5 | B7: Jun 13 | C7: B | D7: Qatar | E7: Switzerland | F7: 0 | G7: 2 | H7: =IF(AND(ISNUMBER(F7),ISNUMBER(G7)),IF(F7>G7,D7,IF(G7>F7,E7,"Draw")),"") -> Switzerland | I7: =IF(AND(ISNUMBER(F7),ISNUMBER(G7)),IF(F7>G7,E7,IF(G7>F7,D7,"Draw")),"") -> Qatar | J7: 1 | K7: 1 | L7: =IF(AND(ISNUMBER(J7),ISNUMBER(K7)),IF(J7>K7,D7,IF(K7>J7,E7,"Draw")),"") -> Draw | M7: =IF(AND(ISNUMBER(J7),ISNUMBER(K7)),IF(J7>K7,E7,IF(K7>J7,D7,"Draw")),"") -> Draw | N7: =IF(AND(ISNUMBER(J7),ISNUMBER(F7)),J7-F7,"") -> 1 | O7: =IF(AND(ISNUMBER(K7),ISNUMBER(G7)),K7-G7,"") -> -1 | P7: =IF(OR(H7="",L7=""),"",IF(H7=L7,1,0)) -> 0
A8: 6 | B8: Jun 13 | C8: C | D8: Brazil | E8: Morocco | F8: 2 | G8: 1 | H8: =IF(AND(ISNUMBER(F8),ISNUMBER(G8)),IF(F8>G8,D8,IF(G8>F8,E8,"Draw")),"") -> Brazil | I8: =IF(AND(ISNUMBER(F8),ISNUMBER(G8)),IF(F8>G8,E8,IF(G8>F8,D8,"Draw")),"") -> Morocco | J8: 1 | K8: 1 | L8: =IF(AND(ISNUMBER(J8),ISNUMBER(K8)),IF(J8>K8,D8,IF(K8>J8,E8,"Draw")),"") -> Draw | M8: =IF(AND(ISNUMBER(J8),ISNUMBER(K8)),IF(J8>K8,E8,IF(K8>J8,D8,"Draw")),"") -> Draw | N8: =IF(AND(ISNUMBER(J8),ISNUMBER(F8)),J8-F8,"") -> -1 | O8: =IF(AND(ISNUMBER(K8),ISNUMBER(G8)),K8-G8,"") -> 0 | P8: =IF(OR(H8="",L8=""),"",IF(H8=L8,1,0)) -> 0
A9: 7 | B9: Jun 13 | C9: C | D9: Haiti | E9: Scotland | F9: 0 | G9: 2 | H9: =IF(AND(ISNUMBER(F9),ISNUMBER(G9)),IF(F9>G9,D9,IF(G9>F9,E9,"Draw")),"") -> Scotland | I9: =IF(AND(ISNUMBER(F9),ISNUMBER(G9)),IF(F9>G9,E9,IF(G9>F9,D9,"Draw")),"") -> Haiti | J9: 0 | K9: 1 | L9: =IF(AND(ISNUMBER(J9),ISNUMBER(K9)),IF(J9>K9,D9,IF(K9>J9,E9,"Draw")),"") -> Scotland | M9: =IF(AND(ISNUMBER(J9),ISNUMBER(K9)),IF(J9>K9,E9,IF(K9>J9,D9,"Draw")),"") -> Haiti | N9: =IF(AND(ISNUMBER(J9),ISNUMBER(F9)),J9-F9,"") -> 0 | O9: =IF(AND(ISNUMBER(K9),ISNUMBER(G9)),K9-G9,"") -> -1 | P9: =IF(OR(H9="",L9=""),"",IF(H9=L9,1,0)) -> 1
A10: 8 | B10: Jun 13 | C10: D | D10: Australia | E10: Türkiye | F10: 0 | G10: 3 | H10: =IF(AND(ISNUMBER(F10),ISNUMBER(G10)),IF(F10>G10,D10,IF(G10>F10,E10,"Draw")),"") -> Türkiye | I10: =IF(AND(ISNUMBER(F10),ISNUMBER(G10)),IF(F10>G10,E10,IF(G10>F10,D10,"Draw")),"") -> Australia | J10: 2 | K10: 0 | L10: =IF(AND(ISNUMBER(J10),ISNUMBER(K10)),IF(J10>K10,D10,IF(K10>J10,E10,"Draw")),"") -> Australia | M10: =IF(AND(ISNUMBER(J10),ISNUMBER(K10)),IF(J10>K10,E10,IF(K10>J10,D10,"Draw")),"") -> Türkiye | N10: =IF(AND(ISNUMBER(J10),ISNUMBER(F10)),J10-F10,"") -> 2 | O10: =IF(AND(ISNUMBER(K10),ISNUMBER(G10)),K10-G10,"") -> -3 | P10: =IF(OR(H10="",L10=""),"",IF(H10=L10,1,0)) -> 0
A11: 9 | B11: Jun 14 | C11: E | D11: Germany | E11: Curaçao | F11: 2 | G11: 0 | H11: =IF(AND(ISNUMBER(F11),ISNUMBER(G11)),IF(F11>G11,D11,IF(G11>F11,E11,"Draw")),"") -> Germany | I11: =IF(AND(ISNUMBER(F11),ISNUMBER(G11)),IF(F11>G11,E11,IF(G11>F11,D11,"Draw")),"") -> Curaçao | J11: 7 | K11: 1 | L11: =IF(AND(ISNUMBER(J11),ISNUMBER(K11)),IF(J11>K11,D11,IF(K11>J11,E11,"Draw")),"") -> Germany | M11: =IF(AND(ISNUMBER(J11),ISNUMBER(K11)),IF(J11>K11,E11,IF(K11>J11,D11,"Draw")),"") -> Curaçao | N11: =IF(AND(ISNUMBER(J11),ISNUMBER(F11)),J11-F11,"") -> 5 | O11: =IF(AND(ISNUMBER(K11),ISNUMBER(G11)),K11-G11,"") -> 1 | P11: =IF(OR(H11="",L11=""),"",IF(H11=L11,1,0)) -> 1
A12: 10 | B12: Jun 14 | C12: F | D12: Netherlands | E12: Japan | F12: 1 | G12: 0 | H12: =IF(AND(ISNUMBER(F12),ISNUMBER(G12)),IF(F12>G12,D12,IF(G12>F12,E12,"Draw")),"") -> Netherlands | I12: =IF(AND(ISNUMBER(F12),ISNUMBER(G12)),IF(F12>G12,E12,IF(G12>F12,D12,"Draw")),"") -> Japan | J12: 2 | K12: 2 | L12: =IF(AND(ISNUMBER(J12),ISNUMBER(K12)),IF(J12>K12,D12,IF(K12>J12,E12,"Draw")),"") -> Draw | M12: =IF(AND(ISNUMBER(J12),ISNUMBER(K12)),IF(J12>K12,E12,IF(K12>J12,D12,"Draw")),"") -> Draw | N12: =IF(AND(ISNUMBER(J12),ISNUMBER(F12)),J12-F12,"") -> 1 | O12: =IF(AND(ISNUMBER(K12),ISNUMBER(G12)),K12-G12,"") -> 2 | P12: =IF(OR(H12="",L12=""),"",IF(H12=L12,1,0)) -> 0
A13: 11 | B13: Jun 14 | C13: E | D13: Côte d'Ivoire | E13: Ecuador | F13: 0 | G13: 2 | H13: =IF(AND(ISNUMBER(F13),ISNUMBER(G13)),IF(F13>G13,D13,IF(G13>F13,E13,"Draw")),"") -> Ecuador | I13: =IF(AND(ISNUMBER(F13),ISNUMBER(G13)),IF(F13>G13,E13,IF(G13>F13,D13,"Draw")),"") -> Côte d'Ivoire | J13: 1 | K13: 0 | L13: =IF(AND(ISNUMBER(J13),ISNUMBER(K13)),IF(J13>K13,D13,IF(K13>J13,E13,"Draw")),"") -> Côte d'Ivoire | M13: =IF(AND(ISNUMBER(J13),ISNUMBER(K13)),IF(J13>K13,E13,IF(K13>J13,D13,"Draw")),"") -> Ecuador | N13: =IF(AND(ISNUMBER(J13),ISNUMBER(F13)),J13-F13,"") -> 1 | O13: =IF(AND(ISNUMBER(K13),ISNUMBER(G13)),K13-G13,"") -> -2 | P13: =IF(OR(H13="",L13=""),"",IF(H13=L13,1,0)) -> 0
A14: 12 | B14: Jun 14 | C14: F | D14: Sweden | E14: Tunisia | F14: 1 | G14: 0 | H14: =IF(AND(ISNUMBER(F14),ISNUMBER(G14)),IF(F14>G14,D14,IF(G14>F14,E14,"Draw")),"") -> Sweden | I14: =IF(AND(ISNUMBER(F14),ISNUMBER(G14)),IF(F14>G14,E14,IF(G14>F14,D14,"Draw")),"") -> Tunisia | J14: 5 | K14: 1 | L14: =IF(AND(ISNUMBER(J14),ISNUMBER(K14)),IF(J14>K14,D14,IF(K14>J14,E14,"Draw")),"") -> Sweden | M14: =IF(AND(ISNUMBER(J14),ISNUMBER(K14)),IF(J14>K14,E14,IF(K14>J14,D14,"Draw")),"") -> Tunisia | N14: =IF(AND(ISNUMBER(J14),ISNUMBER(F14)),J14-F14,"") -> 4 | O14: =IF(AND(ISNUMBER(K14),ISNUMBER(G14)),K14-G14,"") -> 1 | P14: =IF(OR(H14="",L14=""),"",IF(H14=L14,1,0)) -> 1
A15: 13 | B15: Jun 15 | C15: H | D15: Spain | E15: Cabo Verde | F15: 3 | G15: 0 | H15: =IF(AND(ISNUMBER(F15),ISNUMBER(G15)),IF(F15>G15,D15,IF(G15>F15,E15,"Draw")),"") -> Spain | I15: =IF(AND(ISNUMBER(F15),ISNUMBER(G15)),IF(F15>G15,E15,IF(G15>F15,D15,"Draw")),"") -> Cabo Verde | L15: =IF(AND(ISNUMBER(J15),ISNUMBER(K15)),IF(J15>K15,D15,IF(K15>J15,E15,"Draw")),"") | M15: =IF(AND(ISNUMBER(J15),ISNUMBER(K15)),IF(J15>K15,E15,IF(K15>J15,D15,"Draw")),"") | N15: =IF(AND(ISNUMBER(J15),ISNUMBER(F15)),J15-F15,"") | O15: =IF(AND(ISNUMBER(K15),ISNUMBER(G15)),K15-G15,"") | P15: =IF(OR(H15="",L15=""),"",IF(H15=L15,1,0))
A16: 14 | B16: Jun 15 | C16: G | D16: Belgium | E16: Egypt | F16: 1 | G16: 1 | H16: =IF(AND(ISNUMBER(F16),ISNUMBER(G16)),IF(F16>G16,D16,IF(G16>F16,E16,"Draw")),"") -> Draw | I16: =IF(AND(ISNUMBER(F16),ISNUMBER(G16)),IF(F16>G16,E16,IF(G16>F16,D16,"Draw")),"") -> Draw | L16: =IF(AND(ISNUMBER(J16),ISNUMBER(K16)),IF(J16>K16,D16,IF(K16>J16,E16,"Draw")),"") | M16: =IF(AND(ISNUMBER(J16),ISNUMBER(K16)),IF(J16>K16,E16,IF(K16>J16,D16,"Draw")),"") | N16: =IF(AND(ISNUMBER(J16),ISNUMBER(F16)),J16-F16,"") | O16: =IF(AND(ISNUMBER(K16),ISNUMBER(G16)),K16-G16,"") | P16: =IF(OR(H16="",L16=""),"",IF(H16=L16,1,0))
A17: 15 | B17: Jun 15 | C17: H | D17: Saudi Arabia | E17: Uruguay | F17: 0 | G17: 2 | H17: =IF(AND(ISNUMBER(F17),ISNUMBER(G17)),IF(F17>G17,D17,IF(G17>F17,E17,"Draw")),"") -> Uruguay | I17: =IF(AND(ISNUMBER(F17),ISNUMBER(G17)),IF(F17>G17,E17,IF(G17>F17,D17,"Draw")),"") -> Saudi Arabia | L17: =IF(AND(ISNUMBER(J17),ISNUMBER(K17)),IF(J17>K17,D17,IF(K17>J17,E17,"Draw")),"") | M17: =IF(AND(ISNUMBER(J17),ISNUMBER(K17)),IF(J17>K17,E17,IF(K17>J17,D17,"Draw")),"") | N17: =IF(AND(ISNUMBER(J17),ISNUMBER(F17)),J17-F17,"") | O17: =IF(AND(ISNUMBER(K17),ISNUMBER(G17)),K17-G17,"") | P17: =IF(OR(H17="",L17=""),"",IF(H17=L17,1,0))
A18: 16 | B18: Jun 15 | C18: G | D18: Iran | E18: New Zealand | F18: 0 | G18: 0 | H18: =IF(AND(ISNUMBER(F18),ISNUMBER(G18)),IF(F18>G18,D18,IF(G18>F18,E18,"Draw")),"") -> Draw | I18: =IF(AND(ISNUMBER(F18),ISNUMBER(G18)),IF(F18>G18,E18,IF(G18>F18,D18,"Draw")),"") -> Draw | L18: =IF(AND(ISNUMBER(J18),ISNUMBER(K18)),IF(J18>K18,D18,IF(K18>J18,E18,"Draw")),"") | M18: =IF(AND(ISNUMBER(J18),ISNUMBER(K18)),IF(J18>K18,E18,IF(K18>J18,D18,"Draw")),"") | N18: =IF(AND(ISNUMBER(J18),ISNUMBER(F18)),J18-F18,"") | O18: =IF(AND(ISNUMBER(K18),ISNUMBER(G18)),K18-G18,"") | P18: =IF(OR(H18="",L18=""),"",IF(H18=L18,1,0))
A19: 17 | B19: Jun 16 | C19: I | D19: France | E19: Senegal | F19: 3 | G19: 0 | H19: =IF(AND(ISNUMBER(F19),ISNUMBER(G19)),IF(F19>G19,D19,IF(G19>F19,E19,"Draw")),"") -> France | I19: =IF(AND(ISNUMBER(F19),ISNUMBER(G19)),IF(F19>G19,E19,IF(G19>F19,D19,"Draw")),"") -> Senegal | L19: =IF(AND(ISNUMBER(J19),ISNUMBER(K19)),IF(J19>K19,D19,IF(K19>J19,E19,"Draw")),"") | M19: =IF(AND(ISNUMBER(J19),ISNUMBER(K19)),IF(J19>K19,E19,IF(K19>J19,D19,"Draw")),"") | N19: =IF(AND(ISNUMBER(J19),ISNUMBER(F19)),J19-F19,"") | O19: =IF(AND(ISNUMBER(K19),ISNUMBER(G19)),K19-G19,"") | P19: =IF(OR(H19="",L19=""),"",IF(H19=L19,1,0))
A20: 18 | B20: Jun 16 | C20: I | D20: Iraq | E20: Norway | F20: 0 | G20: 2 | H20: =IF(AND(ISNUMBER(F20),ISNUMBER(G20)),IF(F20>G20,D20,IF(G20>F20,E20,"Draw")),"") -> Norway | I20: =IF(AND(ISNUMBER(F20),ISNUMBER(G20)),IF(F20>G20,E20,IF(G20>F20,D20,"Draw")),"") -> Iraq | L20: =IF(AND(ISNUMBER(J20),ISNUMBER(K20)),IF(J20>K20,D20,IF(K20>J20,E20,"Draw")),"") | M20: =IF(AND(ISNUMBER(J20),ISNUMBER(K20)),IF(J20>K20,E20,IF(K20>J20,D20,"Draw")),"") | N20: =IF(AND(ISNUMBER(J20),ISNUMBER(F20)),J20-F20,"") | O20: =IF(AND(ISNUMBER(K20),ISNUMBER(G20)),K20-G20,"") | P20: =IF(OR(H20="",L20=""),"",IF(H20=L20,1,0))
A21: 19 | B21: Jun 16 | C21: J | D21: Argentina | E21: Algeria | F21: 2 | G21: 0 | H21: =IF(AND(ISNUMBER(F21),ISNUMBER(G21)),IF(F21>G21,D21,IF(G21>F21,E21,"Draw")),"") -> Argentina | I21: =IF(AND(ISNUMBER(F21),ISNUMBER(G21)),IF(F21>G21,E21,IF(G21>F21,D21,"Draw")),"") -> Algeria | L21: =IF(AND(ISNUMBER(J21),ISNUMBER(K21)),IF(J21>K21,D21,IF(K21>J21,E21,"Draw")),"") | M21: =IF(AND(ISNUMBER(J21),ISNUMBER(K21)),IF(J21>K21,E21,IF(K21>J21,D21,"Draw")),"") | N21: =IF(AND(ISNUMBER(J21),ISNUMBER(F21)),J21-F21,"") | O21: =IF(AND(ISNUMBER(K21),ISNUMBER(G21)),K21-G21,"") | P21: =IF(OR(H21="",L21=""),"",IF(H21=L21,1,0))
A22: 20 | B22: Jun 16 | C22: J | D22: Austria | E22: Jordan | F22: 1 | G22: 0 | H22: =IF(AND(ISNUMBER(F22),ISNUMBER(G22)),IF(F22>G22,D22,IF(G22>F22,E22,"Draw")),"") -> Austria | I22: =IF(AND(ISNUMBER(F22),ISNUMBER(G22)),IF(F22>G22,E22,IF(G22>F22,D22,"Draw")),"") -> Jordan | L22: =IF(AND(ISNUMBER(J22),ISNUMBER(K22)),IF(J22>K22,D22,IF(K22>J22,E22,"Draw")),"") | M22: =IF(AND(ISNUMBER(J22),ISNUMBER(K22)),IF(J22>K22,E22,IF(K22>J22,D22,"Draw")),"") | N22: =IF(AND(ISNUMBER(J22),ISNUMBER(F22)),J22-F22,"") | O22: =IF(AND(ISNUMBER(K22),ISNUMBER(G22)),K22-G22,"") | P22: =IF(OR(H22="",L22=""),"",IF(H22=L22,1,0))
A23: 21 | B23: Jun 17 | C23: K | D23: Portugal | E23: DR Congo | F23: 3 | G23: 0 | H23: =IF(AND(ISNUMBER(F23),ISNUMBER(G23)),IF(F23>G23,D23,IF(G23>F23,E23,"Draw")),"") -> Portugal | I23: =IF(AND(ISNUMBER(F23),ISNUMBER(G23)),IF(F23>G23,E23,IF(G23>F23,D23,"Draw")),"") -> DR Congo | L23: =IF(AND(ISNUMBER(J23),ISNUMBER(K23)),IF(J23>K23,D23,IF(K23>J23,E23,"Draw")),"") | M23: =IF(AND(ISNUMBER(J23),ISNUMBER(K23)),IF(J23>K23,E23,IF(K23>J23,D23,"Draw")),"") | N23: =IF(AND(ISNUMBER(J23),ISNUMBER(F23)),J23-F23,"") | O23: =IF(AND(ISNUMBER(K23),ISNUMBER(G23)),K23-G23,"") | P23: =IF(OR(H23="",L23=""),"",IF(H23=L23,1,0))
A24: 22 | B24: Jun 17 | C24: L | D24: England | E24: Croatia | F24: 1 | G24: 1 | H24: =IF(AND(ISNUMBER(F24),ISNUMBER(G24)),IF(F24>G24,D24,IF(G24>F24,E24,"Draw")),"") -> Draw | I24: =IF(AND(ISNUMBER(F24),ISNUMBER(G24)),IF(F24>G24,E24,IF(G24>F24,D24,"Draw")),"") -> Draw | L24: =IF(AND(ISNUMBER(J24),ISNUMBER(K24)),IF(J24>K24,D24,IF(K24>J24,E24,"Draw")),"") | M24: =IF(AND(ISNUMBER(J24),ISNUMBER(K24)),IF(J24>K24,E24,IF(K24>J24,D24,"Draw")),"") | N24: =IF(AND(ISNUMBER(J24),ISNUMBER(F24)),J24-F24,"") | O24: =IF(AND(ISNUMBER(K24),ISNUMBER(G24)),K24-G24,"") | P24: =IF(OR(H24="",L24=""),"",IF(H24=L24,1,0))
A25: 23 | B25: Jun 17 | C25: L | D25: Ghana | E25: Panama | F25: 2 | G25: 0 | H25: =IF(AND(ISNUMBER(F25),ISNUMBER(G25)),IF(F25>G25,D25,IF(G25>F25,E25,"Draw")),"") -> Ghana | I25: =IF(AND(ISNUMBER(F25),ISNUMBER(G25)),IF(F25>G25,E25,IF(G25>F25,D25,"Draw")),"") -> Panama | L25: =IF(AND(ISNUMBER(J25),ISNUMBER(K25)),IF(J25>K25,D25,IF(K25>J25,E25,"Draw")),"") | M25: =IF(AND(ISNUMBER(J25),ISNUMBER(K25)),IF(J25>K25,E25,IF(K25>J25,D25,"Draw")),"") | N25: =IF(AND(ISNUMBER(J25),ISNUMBER(F25)),J25-F25,"") | O25: =IF(AND(ISNUMBER(K25),ISNUMBER(G25)),K25-G25,"") | P25: =IF(OR(H25="",L25=""),"",IF(H25=L25,1,0))
A26: 24 | B26: Jun 17 | C26: K | D26: Uzbekistan | E26: Colombia | F26: 0 | G26: 3 | H26: =IF(AND(ISNUMBER(F26),ISNUMBER(G26)),IF(F26>G26,D26,IF(G26>F26,E26,"Draw")),"") -> Colombia | I26: =IF(AND(ISNUMBER(F26),ISNUMBER(G26)),IF(F26>G26,E26,IF(G26>F26,D26,"Draw")),"") -> Uzbekistan | L26: =IF(AND(ISNUMBER(J26),ISNUMBER(K26)),IF(J26>K26,D26,IF(K26>J26,E26,"Draw")),"") | M26: =IF(AND(ISNUMBER(J26),ISNUMBER(K26)),IF(J26>K26,E26,IF(K26>J26,D26,"Draw")),"") | N26: =IF(AND(ISNUMBER(J26),ISNUMBER(F26)),J26-F26,"") | O26: =IF(AND(ISNUMBER(K26),ISNUMBER(G26)),K26-G26,"") | P26: =IF(OR(H26="",L26=""),"",IF(H26=L26,1,0))
... A74: 72 | B74: Jun 27 | C74: J | D74: Jordan | E74: Argentina | F74: 0 | G74: 3 | H74: =IF(AND(ISNUMBER(F74),ISNUMBER(G74)),IF(F74>G74,D74,IF(G74>F74,E74,"Draw")),"") -> Argentina | I74: =IF(AND(ISNUMBER(F74),ISNUMBER(G74)),IF(F74>G74,E74,IF(G74>F74,D74,"Draw")),"") -> Jordan | L74: =IF(AND(ISNUMBER(J74),ISNUMBER(K74)),IF(J74>K74,D74,IF(K74>J74,E74,"Draw")),"") | M74: =IF(AND(ISNUMBER(J74),ISNUMBER(K74)),IF(J74>K74,E74,IF(K74>J74,D74,"Draw")),"") | N74: =IF(AND(ISNUMBER(J74),ISNUMBER(F74)),J74-F74,"") | O74: =IF(AND(ISNUMBER(K74),ISNUMBER(G74)),K74-G74,"") | P74: =IF(OR(H74="",L74=""),"",IF(H74=L74,1,0))

Sheet ENG_Long
A1: Grp | B1: Team | C1: Opp | D1: aGF | E1: aGA | F1: aPld | G1: aW | H1: aD | I1: aL | J1: aPts | K1: pGF | L1: pGA | M1: pPld | N1: pW | O1: pD | P1: pL | Q1: pPts
A2: A | B2: ='Group Matches'!D3 -> Mexico | C2: ='Group Matches'!E3 -> South Africa | D2: =IF(ISNUMBER('Group Matches'!F3),'Group Matches'!F3,0) -> 1 | E2: =IF(ISNUMBER('Group Matches'!G3),'Group Matches'!G3,0) -> 0 | F2: =IF(AND(ISNUMBER('Group Matches'!F3),ISNUMBER('Group Matches'!G3)),1,0) -> 1 | G2: =IF(AND(F2=1,D2>E2),1,0) -> 1 | H2: =IF(AND(F2=1,D2=E2),1,0) -> 0 | I2: =IF(AND(F2=1,D2<E2),1,0) -> 0 | J2: =3*G2+H2 -> 3 | K2: =IF(ISNUMBER('Group Matches'!J3),'Group Matches'!J3,0) -> 2 | L2: =IF(ISNUMBER('Group Matches'!K3),'Group Matches'!K3,0) -> 0 | M2: =IF(AND(ISNUMBER('Group Matches'!J3),ISNUMBER('Group Matches'!K3)),1,0) -> 1 | N2: =IF(AND(M2=1,K2>L2),1,0) -> 1 | O2: =IF(AND(M2=1,K2=L2),1,0) -> 0 | P2: =IF(AND(M2=1,K2<L2),1,0) -> 0 | Q2: =3*N2+O2 -> 3
A3: A | B3: ='Group Matches'!E3 -> South Africa | C3: ='Group Matches'!D3 -> Mexico | D3: =IF(ISNUMBER('Group Matches'!G3),'Group Matches'!G3,0) -> 0 | E3: =IF(ISNUMBER('Group Matches'!F3),'Group Matches'!F3,0) -> 1 | F3: =IF(AND(ISNUMBER('Group Matches'!G3),ISNUMBER('Group Matches'!F3)),1,0) -> 1 | G3: =IF(AND(F3=1,D3>E3),1,0) -> 0 | H3: =IF(AND(F3=1,D3=E3),1,0) -> 0 | I3: =IF(AND(F3=1,D3<E3),1,0) -> 1 | J3: =3*G3+H3 -> 0 | K3: =IF(ISNUMBER('Group Matches'!K3),'Group Matches'!K3,0) -> 0 | L3: =IF(ISNUMBER('Group Matches'!J3),'Group Matches'!J3,0) -> 2 | M3: =IF(AND(ISNUMBER('Group Matches'!K3),ISNUMBER('Group Matches'!J3)),1,0) -> 1 | N3: =IF(AND(M3=1,K3>L3),1,0) -> 0 | O3: =IF(AND(M3=1,K3=L3),1,0) -> 0 | P3: =IF(AND(M3=1,K3<L3),1,0) -> 1 | Q3: =3*N3+O3 -> 0
A4: A | B4: ='Group Matches'!D4 -> South Korea | C4: ='Group Matches'!E4 -> Czechia | D4: =IF(ISNUMBER('Group Matches'!F4),'Group Matches'!F4,0) -> 1 | E4: =IF(ISNUMBER('Group Matches'!G4),'Group Matches'!G4,0) -> 0 | F4: =IF(AND(ISNUMBER('Group Matches'!F4),ISNUMBER('Group Matches'!G4)),1,0) -> 1 | G4: =IF(AND(F4=1,D4>E4),1,0) -> 1 | H4: =IF(AND(F4=1,D4=E4),1,0) -> 0 | I4: =IF(AND(F4=1,D4<E4),1,0) -> 0 | J4: =3*G4+H4 -> 3 | K4: =IF(ISNUMBER('Group Matches'!J4),'Group Matches'!J4,0) -> 2 | L4: =IF(ISNUMBER('Group Matches'!K4),'Group Matches'!K4,0) -> 1 | M4: =IF(AND(ISNUMBER('Group Matches'!J4),ISNUMBER('Group Matches'!K4)),1,0) -> 1 | N4: =IF(AND(M4=1,K4>L4),1,0) -> 1 | O4: =IF(AND(M4=1,K4=L4),1,0) -> 0 | P4: =IF(AND(M4=1,K4<L4),1,0) -> 0 | Q4: =3*N4+O4 -> 3
A5: A | B5: ='Group Matches'!E4 -> Czechia | C5: ='Group Matches'!D4 -> South Korea | D5: =IF(ISNUMBER('Group Matches'!G4),'Group Matches'!G4,0) -> 0 | E5: =IF(ISNUMBER('Group Matches'!F4),'Group Matches'!F4,0) -> 1 | F5: =IF(AND(ISNUMBER('Group Matches'!G4),ISNUMBER('Group Matches'!F4)),1,0) -> 1 | G5: =IF(AND(F5=1,D5>E5),1,0) -> 0 | H5: =IF(AND(F5=1,D5=E5),1,0) -> 0 | I5: =IF(AND(F5=1,D5<E5),1,0) -> 1 | J5: =3*G5+H5 -> 0 | K5: =IF(ISNUMBER('Group Matches'!K4),'Group Matches'!K4,0) -> 1 | L5: =IF(ISNUMBER('Group Matches'!J4),'Group Matches'!J4,0) -> 2 | M5: =IF(AND(ISNUMBER('Group Matches'!K4),ISNUMBER('Group Matches'!J4)),1,0) -> 1 | N5: =IF(AND(M5=1,K5>L5),1,0) -> 0 | O5: =IF(AND(M5=1,K5=L5),1,0) -> 0 | P5: =IF(AND(M5=1,K5<L5),1,0) -> 1 | Q5: =3*N5+O5 -> 0
A6: B | B6: ='Group Matches'!D5 -> Canada | C6: ='Group Matches'!E5 -> Bosnia & Herzegovina | D6: =IF(ISNUMBER('Group Matches'!F5),'Group Matches'!F5,0) -> 0 | E6: =IF(ISNUMBER('Group Matches'!G5),'Group Matches'!G5,0) -> 1 | F6: =IF(AND(ISNUMBER('Group Matches'!F5),ISNUMBER('Group Matches'!G5)),1,0) -> 1 | G6: =IF(AND(F6=1,D6>E6),1,0) -> 0 | H6: =IF(AND(F6=1,D6=E6),1,0) -> 0 | I6: =IF(AND(F6=1,D6<E6),1,0) -> 1 | J6: =3*G6+H6 -> 0 | K6: =IF(ISNUMBER('Group Matches'!J5),'Group Matches'!J5,0) -> 1 | L6: =IF(ISNUMBER('Group Matches'!K5),'Group Matches'!K5,0) -> 1 | M6: =IF(AND(ISNUMBER('Group Matches'!J5),ISNUMBER('Group Matches'!K5)),1,0) -> 1 | N6: =IF(AND(M6=1,K6>L6),1,0) -> 0 | O6: =IF(AND(M6=1,K6=L6),1,0) -> 1 | P6: =IF(AND(M6=1,K6<L6),1,0) -> 0 | Q6: =3*N6+O6 -> 1
A7: B | B7: ='Group Matches'!E5 -> Bosnia & Herzegovina | C7: ='Group Matches'!D5 -> Canada | D7: =IF(ISNUMBER('Group Matches'!G5),'Group Matches'!G5,0) -> 1 | E7: =IF(ISNUMBER('Group Matches'!F5),'Group Matches'!F5,0) -> 0 | F7: =IF(AND(ISNUMBER('Group Matches'!G5),ISNUMBER('Group Matches'!F5)),1,0) -> 1 | G7: =IF(AND(F7=1,D7>E7),1,0) -> 1 | H7: =IF(AND(F7=1,D7=E7),1,0) -> 0 | I7: =IF(AND(F7=1,D7<E7),1,0) -> 0 | J7: =3*G7+H7 -> 3 | K7: =IF(ISNUMBER('Group Matches'!K5),'Group Matches'!K5,0) -> 1 | L7: =IF(ISNUMBER('Group Matches'!J5),'Group Matches'!J5,0) -> 1 | M7: =IF(AND(ISNUMBER('Group Matches'!K5),ISNUMBER('Group Matches'!J5)),1,0) -> 1 | N7: =IF(AND(M7=1,K7>L7),1,0) -> 0 | O7: =IF(AND(M7=1,K7=L7),1,0) -> 1 | P7: =IF(AND(M7=1,K7<L7),1,0) -> 0 | Q7: =3*N7+O7 -> 1
A8: D | B8: ='Group Matches'!D6 -> United States | C8: ='Group Matches'!E6 -> Paraguay | D8: =IF(ISNUMBER('Group Matches'!F6),'Group Matches'!F6,0) -> 2 | E8: =IF(ISNUMBER('Group Matches'!G6),'Group Matches'!G6,0) -> 1 | F8: =IF(AND(ISNUMBER('Group Matches'!F6),ISNUMBER('Group Matches'!G6)),1,0) -> 1 | G8: =IF(AND(F8=1,D8>E8),1,0) -> 1 | H8: =IF(AND(F8=1,D8=E8),1,0) -> 0 | I8: =IF(AND(F8=1,D8<E8),1,0) -> 0 | J8: =3*G8+H8 -> 3 | K8: =IF(ISNUMBER('Group Matches'!J6),'Group Matches'!J6,0) -> 4 | L8: =IF(ISNUMBER('Group Matches'!K6),'Group Matches'!K6,0) -> 1 | M8: =IF(AND(ISNUMBER('Group Matches'!J6),ISNUMBER('Group Matches'!K6)),1,0) -> 1 | N8: =IF(AND(M8=1,K8>L8),1,0) -> 1 | O8: =IF(AND(M8=1,K8=L8),1,0) -> 0 | P8: =IF(AND(M8=1,K8<L8),1,0) -> 0 | Q8: =3*N8+O8 -> 3
A9: D | B9: ='Group Matches'!E6 -> Paraguay | C9: ='Group Matches'!D6 -> United States | D9: =IF(ISNUMBER('Group Matches'!G6),'Group Matches'!G6,0) -> 1 | E9: =IF(ISNUMBER('Group Matches'!F6),'Group Matches'!F6,0) -> 2 | F9: =IF(AND(ISNUMBER('Group Matches'!G6),ISNUMBER('Group Matches'!F6)),1,0) -> 1 | G9: =IF(AND(F9=1,D9>E9),1,0) -> 0 | H9: =IF(AND(F9=1,D9=E9),1,0) -> 0 | I9: =IF(AND(F9=1,D9<E9),1,0) -> 1 | J9: =3*G9+H9 -> 0 | K9: =IF(ISNUMBER('Group Matches'!K6),'Group Matches'!K6,0) -> 1 | L9: =IF(ISNUMBER('Group Matches'!J6),'Group Matches'!J6,0) -> 4 | M9: =IF(AND(ISNUMBER('Group Matches'!K6),ISNUMBER('Group Matches'!J6)),1,0) -> 1 | N9: =IF(AND(M9=1,K9>L9),1,0) -> 0 | O9: =IF(AND(M9=1,K9=L9),1,0) -> 0 | P9: =IF(AND(M9=1,K9<L9),1,0) -> 1 | Q9: =3*N9+O9 -> 0
A10: B | B10: ='Group Matches'!D7 -> Qatar | C10: ='Group Matches'!E7 -> Switzerland | D10: =IF(ISNUMBER('Group Matches'!F7),'Group Matches'!F7,0) -> 0 | E10: =IF(ISNUMBER('Group Matches'!G7),'Group Matches'!G7,0) -> 2 | F10: =IF(AND(ISNUMBER('Group Matches'!F7),ISNUMBER('Group Matches'!G7)),1,0) -> 1 | G10: =IF(AND(F10=1,D10>E10),1,0) -> 0 | H10: =IF(AND(F10=1,D10=E10),1,0) -> 0 | I10: =IF(AND(F10=1,D10<E10),1,0) -> 1 | J10: =3*G10+H10 -> 0 | K10: =IF(ISNUMBER('Group Matches'!J7),'Group Matches'!J7,0) -> 1 | L10: =IF(ISNUMBER('Group Matches'!K7),'Group Matches'!K7,0) -> 1 | M10: =IF(AND(ISNUMBER('Group Matches'!J7),ISNUMBER('Group Matches'!K7)),1,0) -> 1 | N10: =IF(AND(M10=1,K10>L10),1,0) -> 0 | O10: =IF(AND(M10=1,K10=L10),1,0) -> 1 | P10: =IF(AND(M10=1,K10<L10),1,0) -> 0 | Q10: =3*N10+O10 -> 1
A11: B | B11: ='Group Matches'!E7 -> Switzerland | C11: ='Group Matches'!D7 -> Qatar | D11: =IF(ISNUMBER('Group Matches'!G7),'Group Matches'!G7,0) -> 2 | E11: =IF(ISNUMBER('Group Matches'!F7),'Group Matches'!F7,0) -> 0 | F11: =IF(AND(ISNUMBER('Group Matches'!G7),ISNUMBER('Group Matches'!F7)),1,0) -> 1 | G11: =IF(AND(F11=1,D11>E11),1,0) -> 1 | H11: =IF(AND(F11=1,D11=E11),1,0) -> 0 | I11: =IF(AND(F11=1,D11<E11),1,0) -> 0 | J11: =3*G11+H11 -> 3 | K11: =IF(ISNUMBER('Group Matches'!K7),'Group Matches'!K7,0) -> 1 | L11: =IF(ISNUMBER('Group Matches'!J7),'Group Matches'!J7,0) -> 1 | M11: =IF(AND(ISNUMBER('Group Matches'!K7),ISNUMBER('Group Matches'!J7)),1,0) -> 1 | N11: =IF(AND(M11=1,K11>L11),1,0) -> 0 | O11: =IF(AND(M11=1,K11=L11),1,0) -> 1 | P11: =IF(AND(M11=1,K11<L11),1,0) -> 0 | Q11: =3*N11+O11 -> 1
A12: C | B12: ='Group Matches'!D8 -> Brazil | C12: ='Group Matches'!E8 -> Morocco | D12: =IF(ISNUMBER('Group Matches'!F8),'Group Matches'!F8,0) -> 2 | E12: =IF(ISNUMBER('Group Matches'!G8),'Group Matches'!G8,0) -> 1 | F12: =IF(AND(ISNUMBER('Group Matches'!F8),ISNUMBER('Group Matches'!G8)),1,0) -> 1 | G12: =IF(AND(F12=1,D12>E12),1,0) -> 1 | H12: =IF(AND(F12=1,D12=E12),1,0) -> 0 | I12: =IF(AND(F12=1,D12<E12),1,0) -> 0 | J12: =3*G12+H12 -> 3 | K12: =IF(ISNUMBER('Group Matches'!J8),'Group Matches'!J8,0) -> 1 | L12: =IF(ISNUMBER('Group Matches'!K8),'Group Matches'!K8,0) -> 1 | M12: =IF(AND(ISNUMBER('Group Matches'!J8),ISNUMBER('Group Matches'!K8)),1,0) -> 1 | N12: =IF(AND(M12=1,K12>L12),1,0) -> 0 | O12: =IF(AND(M12=1,K12=L12),1,0) -> 1 | P12: =IF(AND(M12=1,K12<L12),1,0) -> 0 | Q12: =3*N12+O12 -> 1
A13: C | B13: ='Group Matches'!E8 -> Morocco | C13: ='Group Matches'!D8 -> Brazil | D13: =IF(ISNUMBER('Group Matches'!G8),'Group Matches'!G8,0) -> 1 | E13: =IF(ISNUMBER('Group Matches'!F8),'Group Matches'!F8,0) -> 2 | F13: =IF(AND(ISNUMBER('Group Matches'!G8),ISNUMBER('Group Matches'!F8)),1,0) -> 1 | G13: =IF(AND(F13=1,D13>E13),1,0) -> 0 | H13: =IF(AND(F13=1,D13=E13),1,0) -> 0 | I13: =IF(AND(F13=1,D13<E13),1,0) -> 1 | J13: =3*G13+H13 -> 0 | K13: =IF(ISNUMBER('Group Matches'!K8),'Group Matches'!K8,0) -> 1 | L13: =IF(ISNUMBER('Group Matches'!J8),'Group Matches'!J8,0) -> 1 | M13: =IF(AND(ISNUMBER('Group Matches'!K8),ISNUMBER('Group Matches'!J8)),1,0) -> 1 | N13: =IF(AND(M13=1,K13>L13),1,0) -> 0 | O13: =IF(AND(M13=1,K13=L13),1,0) -> 1 | P13: =IF(AND(M13=1,K13<L13),1,0) -> 0 | Q13: =3*N13+O13 -> 1
A14: C | B14: ='Group Matches'!D9 -> Haiti | C14: ='Group Matches'!E9 -> Scotland | D14: =IF(ISNUMBER('Group Matches'!F9),'Group Matches'!F9,0) -> 0 | E14: =IF(ISNUMBER('Group Matches'!G9),'Group Matches'!G9,0) -> 2 | F14: =IF(AND(ISNUMBER('Group Matches'!F9),ISNUMBER('Group Matches'!G9)),1,0) -> 1 | G14: =IF(AND(F14=1,D14>E14),1,0) -> 0 | H14: =IF(AND(F14=1,D14=E14),1,0) -> 0 | I14: =IF(AND(F14=1,D14<E14),1,0) -> 1 | J14: =3*G14+H14 -> 0 | K14: =IF(ISNUMBER('Group Matches'!J9),'Group Matches'!J9,0) -> 0 | L14: =IF(ISNUMBER('Group Matches'!K9),'Group Matches'!K9,0) -> 1 | M14: =IF(AND(ISNUMBER('Group Matches'!J9),ISNUMBER('Group Matches'!K9)),1,0) -> 1 | N14: =IF(AND(M14=1,K14>L14),1,0) -> 0 | O14: =IF(AND(M14=1,K14=L14),1,0) -> 0 | P14: =IF(AND(M14=1,K14<L14),1,0) -> 1 | Q14: =3*N14+O14 -> 0
A15: C | B15: ='Group Matches'!E9 -> Scotland | C15: ='Group Matches'!D9 -> Haiti | D15: =IF(ISNUMBER('Group Matches'!G9),'Group Matches'!G9,0) -> 2 | E15: =IF(ISNUMBER('Group Matches'!F9),'Group Matches'!F9,0) -> 0 | F15: =IF(AND(ISNUMBER('Group Matches'!G9),ISNUMBER('Group Matches'!F9)),1,0) -> 1 | G15: =IF(AND(F15=1,D15>E15),1,0) -> 1 | H15: =IF(AND(F15=1,D15=E15),1,0) -> 0 | I15: =IF(AND(F15=1,D15<E15),1,0) -> 0 | J15: =3*G15+H15 -> 3 | K15: =IF(ISNUMBER('Group Matches'!K9),'Group Matches'!K9,0) -> 1 | L15: =IF(ISNUMBER('Group Matches'!J9),'Group Matches'!J9,0) -> 0 | M15: =IF(AND(ISNUMBER('Group Matches'!K9),ISNUMBER('Group Matches'!J9)),1,0) -> 1 | N15: =IF(AND(M15=1,K15>L15),1,0) -> 1 | O15: =IF(AND(M15=1,K15=L15),1,0) -> 0 | P15: =IF(AND(M15=1,K15<L15),1,0) -> 0 | Q15: =3*N15+O15 -> 3
A16: D | B16: ='Group Matches'!D10 -> Australia | C16: ='Group Matches'!E10 -> Türkiye | D16: =IF(ISNUMBER('Group Matches'!F10),'Group Matches'!F10,0) -> 0 | E16: =IF(ISNUMBER('Group Matches'!G10),'Group Matches'!G10,0) -> 3 | F16: =IF(AND(ISNUMBER('Group Matches'!F10),ISNUMBER('Group Matches'!G10)),1,0) -> 1 | G16: =IF(AND(F16=1,D16>E16),1,0) -> 0 | H16: =IF(AND(F16=1,D16=E16),1,0) -> 0 | I16: =IF(AND(F16=1,D16<E16),1,0) -> 1 | J16: =3*G16+H16 -> 0 | K16: =IF(ISNUMBER('Group Matches'!J10),'Group Matches'!J10,0) -> 2 | L16: =IF(ISNUMBER('Group Matches'!K10),'Group Matches'!K10,0) -> 0 | M16: =IF(AND(ISNUMBER('Group Matches'!J10),ISNUMBER('Group Matches'!K10)),1,0) -> 1 | N16: =IF(AND(M16=1,K16>L16),1,0) -> 1 | O16: =IF(AND(M16=1,K16=L16),1,0) -> 0 | P16: =IF(AND(M16=1,K16<L16),1,0) -> 0 | Q16: =3*N16+O16 -> 3
A17: D | B17: ='Group Matches'!E10 -> Türkiye | C17: ='Group Matches'!D10 -> Australia | D17: =IF(ISNUMBER('Group Matches'!G10),'Group Matches'!G10,0) -> 3 | E17: =IF(ISNUMBER('Group Matches'!F10),'Group Matches'!F10,0) -> 0 | F17: =IF(AND(ISNUMBER('Group Matches'!G10),ISNUMBER('Group Matches'!F10)),1,0) -> 1 | G17: =IF(AND(F17=1,D17>E17),1,0) -> 1 | H17: =IF(AND(F17=1,D17=E17),1,0) -> 0 | I17: =IF(AND(F17=1,D17<E17),1,0) -> 0 | J17: =3*G17+H17 -> 3 | K17: =IF(ISNUMBER('Group Matches'!K10),'Group Matches'!K10,0) -> 0 | L17: =IF(ISNUMBER('Group Matches'!J10),'Group Matches'!J10,0) -> 2 | M17: =IF(AND(ISNUMBER('Group Matches'!K10),ISNUMBER('Group Matches'!J10)),1,0) -> 1 | N17: =IF(AND(M17=1,K17>L17),1,0) -> 0 | O17: =IF(AND(M17=1,K17=L17),1,0) -> 0 | P17: =IF(AND(M17=1,K17<L17),1,0) -> 1 | Q17: =3*N17+O17 -> 0
A18: E | B18: ='Group Matches'!D11 -> Germany | C18: ='Group Matches'!E11 -> Curaçao | D18: =IF(ISNUMBER('Group Matches'!F11),'Group Matches'!F11,0) -> 2 | E18: =IF(ISNUMBER('Group Matches'!G11),'Group Matches'!G11,0) -> 0 | F18: =IF(AND(ISNUMBER('Group Matches'!F11),ISNUMBER('Group Matches'!G11)),1,0) -> 1 | G18: =IF(AND(F18=1,D18>E18),1,0) -> 1 | H18: =IF(AND(F18=1,D18=E18),1,0) -> 0 | I18: =IF(AND(F18=1,D18<E18),1,0) -> 0 | J18: =3*G18+H18 -> 3 | K18: =IF(ISNUMBER('Group Matches'!J11),'Group Matches'!J11,0) -> 7 | L18: =IF(ISNUMBER('Group Matches'!K11),'Group Matches'!K11,0) -> 1 | M18: =IF(AND(ISNUMBER('Group Matches'!J11),ISNUMBER('Group Matches'!K11)),1,0) -> 1 | N18: =IF(AND(M18=1,K18>L18),1,0) -> 1 | O18: =IF(AND(M18=1,K18=L18),1,0) -> 0 | P18: =IF(AND(M18=1,K18<L18),1,0) -> 0 | Q18: =3*N18+O18 -> 3
A19: E | B19: ='Group Matches'!E11 -> Curaçao | C19: ='Group Matches'!D11 -> Germany | D19: =IF(ISNUMBER('Group Matches'!G11),'Group Matches'!G11,0) -> 0 | E19: =IF(ISNUMBER('Group Matches'!F11),'Group Matches'!F11,0) -> 2 | F19: =IF(AND(ISNUMBER('Group Matches'!G11),ISNUMBER('Group Matches'!F11)),1,0) -> 1 | G19: =IF(AND(F19=1,D19>E19),1,0) -> 0 | H19: =IF(AND(F19=1,D19=E19),1,0) -> 0 | I19: =IF(AND(F19=1,D19<E19),1,0) -> 1 | J19: =3*G19+H19 -> 0 | K19: =IF(ISNUMBER('Group Matches'!K11),'Group Matches'!K11,0) -> 1 | L19: =IF(ISNUMBER('Group Matches'!J11),'Group Matches'!J11,0) -> 7 | M19: =IF(AND(ISNUMBER('Group Matches'!K11),ISNUMBER('Group Matches'!J11)),1,0) -> 1 | N19: =IF(AND(M19=1,K19>L19),1,0) -> 0 | O19: =IF(AND(M19=1,K19=L19),1,0) -> 0 | P19: =IF(AND(M19=1,K19<L19),1,0) -> 1 | Q19: =3*N19+O19 -> 0
A20: F | B20: ='Group Matches'!D12 -> Netherlands | C20: ='Group Matches'!E12 -> Japan | D20: =IF(ISNUMBER('Group Matches'!F12),'Group Matches'!F12,0) -> 1 | E20: =IF(ISNUMBER('Group Matches'!G12),'Group Matches'!G12,0) -> 0 | F20: =IF(AND(ISNUMBER('Group Matches'!F12),ISNUMBER('Group Matches'!G12)),1,0) -> 1 | G20: =IF(AND(F20=1,D20>E20),1,0) -> 1 | H20: =IF(AND(F20=1,D20=E20),1,0) -> 0 | I20: =IF(AND(F20=1,D20<E20),1,0) -> 0 | J20: =3*G20+H20 -> 3 | K20: =IF(ISNUMBER('Group Matches'!J12),'Group Matches'!J12,0) -> 2 | L20: =IF(ISNUMBER('Group Matches'!K12),'Group Matches'!K12,0) -> 2 | M20: =IF(AND(ISNUMBER('Group Matches'!J12),ISNUMBER('Group Matches'!K12)),1,0) -> 1 | N20: =IF(AND(M20=1,K20>L20),1,0) -> 0 | O20: =IF(AND(M20=1,K20=L20),1,0) -> 1 | P20: =IF(AND(M20=1,K20<L20),1,0) -> 0 | Q20: =3*N20+O20 -> 1
A21: F | B21: ='Group Matches'!E12 -> Japan | C21: ='Group Matches'!D12 -> Netherlands | D21: =IF(ISNUMBER('Group Matches'!G12),'Group Matches'!G12,0) -> 0 | E21: =IF(ISNUMBER('Group Matches'!F12),'Group Matches'!F12,0) -> 1 | F21: =IF(AND(ISNUMBER('Group Matches'!G12),ISNUMBER('Group Matches'!F12)),1,0) -> 1 | G21: =IF(AND(F21=1,D21>E21),1,0) -> 0 | H21: =IF(AND(F21=1,D21=E21),1,0) -> 0 | I21: =IF(AND(F21=1,D21<E21),1,0) -> 1 | J21: =3*G21+H21 -> 0 | K21: =IF(ISNUMBER('Group Matches'!K12),'Group Matches'!K12,0) -> 2 | L21: =IF(ISNUMBER('Group Matches'!J12),'Group Matches'!J12,0) -> 2 | M21: =IF(AND(ISNUMBER('Group Matches'!K12),ISNUMBER('Group Matches'!J12)),1,0) -> 1 | N21: =IF(AND(M21=1,K21>L21),1,0) -> 0 | O21: =IF(AND(M21=1,K21=L21),1,0) -> 1 | P21: =IF(AND(M21=1,K21<L21),1,0) -> 0 | Q21: =3*N21+O21 -> 1
A22: E | B22: ='Group Matches'!D13 -> Côte d'Ivoire | C22: ='Group Matches'!E13 -> Ecuador | D22: =IF(ISNUMBER('Group Matches'!F13),'Group Matches'!F13,0) -> 0 | E22: =IF(ISNUMBER('Group Matches'!G13),'Group Matches'!G13,0) -> 2 | F22: =IF(AND(ISNUMBER('Group Matches'!F13),ISNUMBER('Group Matches'!G13)),1,0) -> 1 | G22: =IF(AND(F22=1,D22>E22),1,0) -> 0 | H22: =IF(AND(F22=1,D22=E22),1,0) -> 0 | I22: =IF(AND(F22=1,D22<E22),1,0) -> 1 | J22: =3*G22+H22 -> 0 | K22: =IF(ISNUMBER('Group Matches'!J13),'Group Matches'!J13,0) -> 1 | L22: =IF(ISNUMBER('Group Matches'!K13),'Group Matches'!K13,0) -> 0 | M22: =IF(AND(ISNUMBER('Group Matches'!J13),ISNUMBER('Group Matches'!K13)),1,0) -> 1 | N22: =IF(AND(M22=1,K22>L22),1,0) -> 1 | O22: =IF(AND(M22=1,K22=L22),1,0) -> 0 | P22: =IF(AND(M22=1,K22<L22),1,0) -> 0 | Q22: =3*N22+O22 -> 3
A23: E | B23: ='Group Matches'!E13 -> Ecuador | C23: ='Group Matches'!D13 -> Côte d'Ivoire | D23: =IF(ISNUMBER('Group Matches'!G13),'Group Matches'!G13,0) -> 2 | E23: =IF(ISNUMBER('Group Matches'!F13),'Group Matches'!F13,0) -> 0 | F23: =IF(AND(ISNUMBER('Group Matches'!G13),ISNUMBER('Group Matches'!F13)),1,0) -> 1 | G23: =IF(AND(F23=1,D23>E23),1,0) -> 1 | H23: =IF(AND(F23=1,D23=E23),1,0) -> 0 | I23: =IF(AND(F23=1,D23<E23),1,0) -> 0 | J23: =3*G23+H23 -> 3 | K23: =IF(ISNUMBER('Group Matches'!K13),'Group Matches'!K13,0) -> 0 | L23: =IF(ISNUMBER('Group Matches'!J13),'Group Matches'!J13,0) -> 1 | M23: =IF(AND(ISNUMBER('Group Matches'!K13),ISNUMBER('Group Matches'!J13)),1,0) -> 1 | N23: =IF(AND(M23=1,K23>L23),1,0) -> 0 | O23: =IF(AND(M23=1,K23=L23),1,0) -> 0 | P23: =IF(AND(M23=1,K23<L23),1,0) -> 1 | Q23: =3*N23+O23 -> 0
A24: F | B24: ='Group Matches'!D14 -> Sweden | C24: ='Group Matches'!E14 -> Tunisia | D24: =IF(ISNUMBER('Group Matches'!F14),'Group Matches'!F14,0) -> 1 | E24: =IF(ISNUMBER('Group Matches'!G14),'Group Matches'!G14,0) -> 0 | F24: =IF(AND(ISNUMBER('Group Matches'!F14),ISNUMBER('Group Matches'!G14)),1,0) -> 1 | G24: =IF(AND(F24=1,D24>E24),1,0) -> 1 | H24: =IF(AND(F24=1,D24=E24),1,0) -> 0 | I24: =IF(AND(F24=1,D24<E24),1,0) -> 0 | J24: =3*G24+H24 -> 3 | K24: =IF(ISNUMBER('Group Matches'!J14),'Group Matches'!J14,0) -> 5 | L24: =IF(ISNUMBER('Group Matches'!K14),'Group Matches'!K14,0) -> 1 | M24: =IF(AND(ISNUMBER('Group Matches'!J14),ISNUMBER('Group Matches'!K14)),1,0) -> 1 | N24: =IF(AND(M24=1,K24>L24),1,0) -> 1 | O24: =IF(AND(M24=1,K24=L24),1,0) -> 0 | P24: =IF(AND(M24=1,K24<L24),1,0) -> 0 | Q24: =3*N24+O24 -> 3
A25: F | B25: ='Group Matches'!E14 -> Tunisia | C25: ='Group Matches'!D14 -> Sweden | D25: =IF(ISNUMBER('Group Matches'!G14),'Group Matches'!G14,0) -> 0 | E25: =IF(ISNUMBER('Group Matches'!F14),'Group Matches'!F14,0) -> 1 | F25: =IF(AND(ISNUMBER('Group Matches'!G14),ISNUMBER('Group Matches'!F14)),1,0) -> 1 | G25: =IF(AND(F25=1,D25>E25),1,0) -> 0 | H25: =IF(AND(F25=1,D25=E25),1,0) -> 0 | I25: =IF(AND(F25=1,D25<E25),1,0) -> 1 | J25: =3*G25+H25 -> 0 | K25: =IF(ISNUMBER('Group Matches'!K14),'Group Matches'!K14,0) -> 1 | L25: =IF(ISNUMBER('Group Matches'!J14),'Group Matches'!J14,0) -> 5 | M25: =IF(AND(ISNUMBER('Group Matches'!K14),ISNUMBER('Group Matches'!J14)),1,0) -> 1 | N25: =IF(AND(M25=1,K25>L25),1,0) -> 0 | O25: =IF(AND(M25=1,K25=L25),1,0) -> 0 | P25: =IF(AND(M25=1,K25<L25),1,0) -> 1 | Q25: =3*N25+O25 -> 0
A26: H | B26: ='Group Matches'!D15 -> Spain | C26: ='Group Matches'!E15 -> Cabo Verde | D26: =IF(ISNUMBER('Group Matches'!F15),'Group Matches'!F15,0) -> 3 | E26: =IF(ISNUMBER('Group Matches'!G15),'Group Matches'!G15,0) -> 0 | F26: =IF(AND(ISNUMBER('Group Matches'!F15),ISNUMBER('Group Matches'!G15)),1,0) -> 1 | G26: =IF(AND(F26=1,D26>E26),1,0) -> 1 | H26: =IF(AND(F26=1,D26=E26),1,0) -> 0 | I26: =IF(AND(F26=1,D26<E26),1,0) -> 0 | J26: =3*G26+H26 -> 3 | K26: =IF(ISNUMBER('Group Matches'!J15),'Group Matches'!J15,0) -> 0 | L26: =IF(ISNUMBER('Group Matches'!K15),'Group Matches'!K15,0) -> 0 | M26: =IF(AND(ISNUMBER('Group Matches'!J15),ISNUMBER('Group Matches'!K15)),1,0) -> 0 | N26: =IF(AND(M26=1,K26>L26),1,0) -> 0 | O26: =IF(AND(M26=1,K26=L26),1,0) -> 0 | P26: =IF(AND(M26=1,K26<L26),1,0) -> 0 | Q26: =3*N26+O26 -> 0
A27: H | B27: ='Group Matches'!E15 -> Cabo Verde | C27: ='Group Matches'!D15 -> Spain | D27: =IF(ISNUMBER('Group Matches'!G15),'Group Matches'!G15,0) -> 0 | E27: =IF(ISNUMBER('Group Matches'!F15),'Group Matches'!F15,0) -> 3 | F27: =IF(AND(ISNUMBER('Group Matches'!G15),ISNUMBER('Group Matches'!F15)),1,0) -> 1 | G27: =IF(AND(F27=1,D27>E27),1,0) -> 0 | H27: =IF(AND(F27=1,D27=E27),1,0) -> 0 | I27: =IF(AND(F27=1,D27<E27),1,0) -> 1 | J27: =3*G27+H27 -> 0 | K27: =IF(ISNUMBER('Group Matches'!K15),'Group Matches'!K15,0) -> 0 | L27: =IF(ISNUMBER('Group Matches'!J15),'Group Matches'!J15,0) -> 0 | M27: =IF(AND(ISNUMBER('Group Matches'!K15),ISNUMBER('Group Matches'!J15)),1,0) -> 0 | N27: =IF(AND(M27=1,K27>L27),1,0) -> 0 | O27: =IF(AND(M27=1,K27=L27),1,0) -> 0 | P27: =IF(AND(M27=1,K27<L27),1,0) -> 0 | Q27: =3*N27+O27 -> 0
A28: G | B28: ='Group Matches'!D16 -> Belgium | C28: ='Group Matches'!E16 -> Egypt | D28: =IF(ISNUMBER('Group Matches'!F16),'Group Matches'!F16,0) -> 1 | E28: =IF(ISNUMBER('Group Matches'!G16),'Group Matches'!G16,0) -> 1 | F28: =IF(AND(ISNUMBER('Group Matches'!F16),ISNUMBER('Group Matches'!G16)),1,0) -> 1 | G28: =IF(AND(F28=1,D28>E28),1,0) -> 0 | H28: =IF(AND(F28=1,D28=E28),1,0) -> 1 | I28: =IF(AND(F28=1,D28<E28),1,0) -> 0 | J28: =3*G28+H28 -> 1 | K28: =IF(ISNUMBER('Group Matches'!J16),'Group Matches'!J16,0) -> 0 | L28: =IF(ISNUMBER('Group Matches'!K16),'Group Matches'!K16,0) -> 0 | M28: =IF(AND(ISNUMBER('Group Matches'!J16),ISNUMBER('Group Matches'!K16)),1,0) -> 0 | N28: =IF(AND(M28=1,K28>L28),1,0) -> 0 | O28: =IF(AND(M28=1,K28=L28),1,0) -> 0 | P28: =IF(AND(M28=1,K28<L28),1,0) -> 0 | Q28: =3*N28+O28 -> 0
A29: G | B29: ='Group Matches'!E16 -> Egypt | C29: ='Group Matches'!D16 -> Belgium | D29: =IF(ISNUMBER('Group Matches'!G16),'Group Matches'!G16,0) -> 1 | E29: =IF(ISNUMBER('Group Matches'!F16),'Group Matches'!F16,0) -> 1 | F29: =IF(AND(ISNUMBER('Group Matches'!G16),ISNUMBER('Group Matches'!F16)),1,0) -> 1 | G29: =IF(AND(F29=1,D29>E29),1,0) -> 0 | H29: =IF(AND(F29=1,D29=E29),1,0) -> 1 | I29: =IF(AND(F29=1,D29<E29),1,0) -> 0 | J29: =3*G29+H29 -> 1 | K29: =IF(ISNUMBER('Group Matches'!K16),'Group Matches'!K16,0) -> 0 | L29: =IF(ISNUMBER('Group Matches'!J16),'Group Matches'!J16,0) -> 0 | M29: =IF(AND(ISNUMBER('Group Matches'!K16),ISNUMBER('Group Matches'!J16)),1,0) -> 0 | N29: =IF(AND(M29=1,K29>L29),1,0) -> 0 | O29: =IF(AND(M29=1,K29=L29),1,0) -> 0 | P29: =IF(AND(M29=1,K29<L29),1,0) -> 0 | Q29: =3*N29+O29 -> 0
A30: H | B30: ='Group Matches'!D17 -> Saudi Arabia | C30: ='Group Matches'!E17 -> Uruguay | D30: =IF(ISNUMBER('Group Matches'!F17),'Group Matches'!F17,0) -> 0 | E30: =IF(ISNUMBER('Group Matches'!G17),'Group Matches'!G17,0) -> 2 | F30: =IF(AND(ISNUMBER('Group Matches'!F17),ISNUMBER('Group Matches'!G17)),1,0) -> 1 | G30: =IF(AND(F30=1,D30>E30),1,0) -> 0 | H30: =IF(AND(F30=1,D30=E30),1,0) -> 0 | I30: =IF(AND(F30=1,D30<E30),1,0) -> 1 | J30: =3*G30+H30 -> 0 | K30: =IF(ISNUMBER('Group Matches'!J17),'Group Matches'!J17,0) -> 0 | L30: =IF(ISNUMBER('Group Matches'!K17),'Group Matches'!K17,0) -> 0 | M30: =IF(AND(ISNUMBER('Group Matches'!J17),ISNUMBER('Group Matches'!K17)),1,0) -> 0 | N30: =IF(AND(M30=1,K30>L30),1,0) -> 0 | O30: =IF(AND(M30=1,K30=L30),1,0) -> 0 | P30: =IF(AND(M30=1,K30<L30),1,0) -> 0 | Q30: =3*N30+O30 -> 0
A31: H | B31: ='Group Matches'!E17 -> Uruguay | C31: ='Group Matches'!D17 -> Saudi Arabia | D31: =IF(ISNUMBER('Group Matches'!G17),'Group Matches'!G17,0) -> 2 | E31: =IF(ISNUMBER('Group Matches'!F17),'Group Matches'!F17,0) -> 0 | F31: =IF(AND(ISNUMBER('Group Matches'!G17),ISNUMBER('Group Matches'!F17)),1,0) -> 1 | G31: =IF(AND(F31=1,D31>E31),1,0) -> 1 | H31: =IF(AND(F31=1,D31=E31),1,0) -> 0 | I31: =IF(AND(F31=1,D31<E31),1,0) -> 0 | J31: =3*G31+H31 -> 3 | K31: =IF(ISNUMBER('Group Matches'!K17),'Group Matches'!K17,0) -> 0 | L31: =IF(ISNUMBER('Group Matches'!J17),'Group Matches'!J17,0) -> 0 | M31: =IF(AND(ISNUMBER('Group Matches'!K17),ISNUMBER('Group Matches'!J17)),1,0) -> 0 | N31: =IF(AND(M31=1,K31>L31),1,0) -> 0 | O31: =IF(AND(M31=1,K31=L31),1,0) -> 0 | P31: =IF(AND(M31=1,K31<L31),1,0) -> 0 | Q31: =3*N31+O31 -> 0
A32: G | B32: ='Group Matches'!D18 -> Iran | C32: ='Group Matches'!E18 -> New Zealand | D32: =IF(ISNUMBER('Group Matches'!F18),'Group Matches'!F18,0) -> 0 | E32: =IF(ISNUMBER('Group Matches'!G18),'Group Matches'!G18,0) -> 0 | F32: =IF(AND(ISNUMBER('Group Matches'!F18),ISNUMBER('Group Matches'!G18)),1,0) -> 1 | G32: =IF(AND(F32=1,D32>E32),1,0) -> 0 | H32: =IF(AND(F32=1,D32=E32),1,0) -> 1 | I32: =IF(AND(F32=1,D32<E32),1,0) -> 0 | J32: =3*G32+H32 -> 1 | K32: =IF(ISNUMBER('Group Matches'!J18),'Group Matches'!J18,0) -> 0 | L32: =IF(ISNUMBER('Group Matches'!K18),'Group Matches'!K18,0) -> 0 | M32: =IF(AND(ISNUMBER('Group Matches'!J18),ISNUMBER('Group Matches'!K18)),1,0) -> 0 | N32: =IF(AND(M32=1,K32>L32),1,0) -> 0 | O32: =IF(AND(M32=1,K32=L32),1,0) -> 0 | P32: =IF(AND(M32=1,K32<L32),1,0) -> 0 | Q32: =3*N32+O32 -> 0
A33: G | B33: ='Group Matches'!E18 -> New Zealand | C33: ='Group Matches'!D18 -> Iran | D33: =IF(ISNUMBER('Group Matches'!G18),'Group Matches'!G18,0) -> 0 | E33: =IF(ISNUMBER('Group Matches'!F18),'Group Matches'!F18,0) -> 0 | F33: =IF(AND(ISNUMBER('Group Matches'!G18),ISNUMBER('Group Matches'!F18)),1,0) -> 1 | G33: =IF(AND(F33=1,D33>E33),1,0) -> 0 | H33: =IF(AND(F33=1,D33=E33),1,0) -> 1 | I33: =IF(AND(F33=1,D33<E33),1,0) -> 0 | J33: =3*G33+H33 -> 1 | K33: =IF(ISNUMBER('Group Matches'!K18),'Group Matches'!K18,0) -> 0 | L33: =IF(ISNUMBER('Group Matches'!J18),'Group Matches'!J18,0) -> 0 | M33: =IF(AND(ISNUMBER('Group Matches'!K18),ISNUMBER('Group Matches'!J18)),1,0) -> 0 | N33: =IF(AND(M33=1,K33>L33),1,0) -> 0 | O33: =IF(AND(M33=1,K33=L33),1,0) -> 0 | P33: =IF(AND(M33=1,K33<L33),1,0) -> 0 | Q33: =3*N33+O33 -> 0
A34: I | B34: ='Group Matches'!D19 -> France | C34: ='Group Matches'!E19 -> Senegal | D34: =IF(ISNUMBER('Group Matches'!F19),'Group Matches'!F19,0) -> 3 | E34: =IF(ISNUMBER('Group Matches'!G19),'Group Matches'!G19,0) -> 0 | F34: =IF(AND(ISNUMBER('Group Matches'!F19),ISNUMBER('Group Matches'!G19)),1,0) -> 1 | G34: =IF(AND(F34=1,D34>E34),1,0) -> 1 | H34: =IF(AND(F34=1,D34=E34),1,0) -> 0 | I34: =IF(AND(F34=1,D34<E34),1,0) -> 0 | J34: =3*G34+H34 -> 3 | K34: =IF(ISNUMBER('Group Matches'!J19),'Group Matches'!J19,0) -> 0 | L34: =IF(ISNUMBER('Group Matches'!K19),'Group Matches'!K19,0) -> 0 | M34: =IF(AND(ISNUMBER('Group Matches'!J19),ISNUMBER('Group Matches'!K19)),1,0) -> 0 | N34: =IF(AND(M34=1,K34>L34),1,0) -> 0 | O34: =IF(AND(M34=1,K34=L34),1,0) -> 0 | P34: =IF(AND(M34=1,K34<L34),1,0) -> 0 | Q34: =3*N34+O34 -> 0
A35: I | B35: ='Group Matches'!E19 -> Senegal | C35: ='Group Matches'!D19 -> France | D35: =IF(ISNUMBER('Group Matches'!G19),'Group Matches'!G19,0) -> 0 | E35: =IF(ISNUMBER('Group Matches'!F19),'Group Matches'!F19,0) -> 3 | F35: =IF(AND(ISNUMBER('Group Matches'!G19),ISNUMBER('Group Matches'!F19)),1,0) -> 1 | G35: =IF(AND(F35=1,D35>E35),1,0) -> 0 | H35: =IF(AND(F35=1,D35=E35),1,0) -> 0 | I35: =IF(AND(F35=1,D35<E35),1,0) -> 1 | J35: =3*G35+H35 -> 0 | K35: =IF(ISNUMBER('Group Matches'!K19),'Group Matches'!K19,0) -> 0 | L35: =IF(ISNUMBER('Group Matches'!J19),'Group Matches'!J19,0) -> 0 | M35: =IF(AND(ISNUMBER('Group Matches'!K19),ISNUMBER('Group Matches'!J19)),1,0) -> 0 | N35: =IF(AND(M35=1,K35>L35),1,0) -> 0 | O35: =IF(AND(M35=1,K35=L35),1,0) -> 0 | P35: =IF(AND(M35=1,K35<L35),1,0) -> 0 | Q35: =3*N35+O35 -> 0
A36: I | B36: ='Group Matches'!D20 -> Iraq | C36: ='Group Matches'!E20 -> Norway | D36: =IF(ISNUMBER('Group Matches'!F20),'Group Matches'!F20,0) -> 0 | E36: =IF(ISNUMBER('Group Matches'!G20),'Group Matches'!G20,0) -> 2 | F36: =IF(AND(ISNUMBER('Group Matches'!F20),ISNUMBER('Group Matches'!G20)),1,0) -> 1 | G36: =IF(AND(F36=1,D36>E36),1,0) -> 0 | H36: =IF(AND(F36=1,D36=E36),1,0) -> 0 | I36: =IF(AND(F36=1,D36<E36),1,0) -> 1 | J36: =3*G36+H36 -> 0 | K36: =IF(ISNUMBER('Group Matches'!J20),'Group Matches'!J20,0) -> 0 | L36: =IF(ISNUMBER('Group Matches'!K20),'Group Matches'!K20,0) -> 0 | M36: =IF(AND(ISNUMBER('Group Matches'!J20),ISNUMBER('Group Matches'!K20)),1,0) -> 0 | N36: =IF(AND(M36=1,K36>L36),1,0) -> 0 | O36: =IF(AND(M36=1,K36=L36),1,0) -> 0 | P36: =IF(AND(M36=1,K36<L36),1,0) -> 0 | Q36: =3*N36+O36 -> 0
A37: I | B37: ='Group Matches'!E20 -> Norway | C37: ='Group Matches'!D20 -> Iraq | D37: =IF(ISNUMBER('Group Matches'!G20),'Group Matches'!G20,0) -> 2 | E37: =IF(ISNUMBER('Group Matches'!F20),'Group Matches'!F20,0) -> 0 | F37: =IF(AND(ISNUMBER('Group Matches'!G20),ISNUMBER('Group Matches'!F20)),1,0) -> 1 | G37: =IF(AND(F37=1,D37>E37),1,0) -> 1 | H37: =IF(AND(F37=1,D37=E37),1,0) -> 0 | I37: =IF(AND(F37=1,D37<E37),1,0) -> 0 | J37: =3*G37+H37 -> 3 | K37: =IF(ISNUMBER('Group Matches'!K20),'Group Matches'!K20,0) -> 0 | L37: =IF(ISNUMBER('Group Matches'!J20),'Group Matches'!J20,0) -> 0 | M37: =IF(AND(ISNUMBER('Group Matches'!K20),ISNUMBER('Group Matches'!J20)),1,0) -> 0 | N37: =IF(AND(M37=1,K37>L37),1,0) -> 0 | O37: =IF(AND(M37=1,K37=L37),1,0) -> 0 | P37: =IF(AND(M37=1,K37<L37),1,0) -> 0 | Q37: =3*N37+O37 -> 0
A38: J | B38: ='Group Matches'!D21 -> Argentina | C38: ='Group Matches'!E21 -> Algeria | D38: =IF(ISNUMBER('Group Matches'!F21),'Group Matches'!F21,0) -> 2 | E38: =IF(ISNUMBER('Group Matches'!G21),'Group Matches'!G21,0) -> 0 | F38: =IF(AND(ISNUMBER('Group Matches'!F21),ISNUMBER('Group Matches'!G21)),1,0) -> 1 | G38: =IF(AND(F38=1,D38>E38),1,0) -> 1 | H38: =IF(AND(F38=1,D38=E38),1,0) -> 0 | I38: =IF(AND(F38=1,D38<E38),1,0) -> 0 | J38: =3*G38+H38 -> 3 | K38: =IF(ISNUMBER('Group Matches'!J21),'Group Matches'!J21,0) -> 0 | L38: =IF(ISNUMBER('Group Matches'!K21),'Group Matches'!K21,0) -> 0 | M38: =IF(AND(ISNUMBER('Group Matches'!J21),ISNUMBER('Group Matches'!K21)),1,0) -> 0 | N38: =IF(AND(M38=1,K38>L38),1,0) -> 0 | O38: =IF(AND(M38=1,K38=L38),1,0) -> 0 | P38: =IF(AND(M38=1,K38<L38),1,0) -> 0 | Q38: =3*N38+O38 -> 0
A39: J | B39: ='Group Matches'!E21 -> Algeria | C39: ='Group Matches'!D21 -> Argentina | D39: =IF(ISNUMBER('Group Matches'!G21),'Group Matches'!G21,0) -> 0 | E39: =IF(ISNUMBER('Group Matches'!F21),'Group Matches'!F21,0) -> 2 | F39: =IF(AND(ISNUMBER('Group Matches'!G21),ISNUMBER('Group Matches'!F21)),1,0) -> 1 | G39: =IF(AND(F39=1,D39>E39),1,0) -> 0 | H39: =IF(AND(F39=1,D39=E39),1,0) -> 0 | I39: =IF(AND(F39=1,D39<E39),1,0) -> 1 | J39: =3*G39+H39 -> 0 | K39: =IF(ISNUMBER('Group Matches'!K21),'Group Matches'!K21,0) -> 0 | L39: =IF(ISNUMBER('Group Matches'!J21),'Group Matches'!J21,0) -> 0 | M39: =IF(AND(ISNUMBER('Group Matches'!K21),ISNUMBER('Group Matches'!J21)),1,0) -> 0 | N39: =IF(AND(M39=1,K39>L39),1,0) -> 0 | O39: =IF(AND(M39=1,K39=L39),1,0) -> 0 | P39: =IF(AND(M39=1,K39<L39),1,0) -> 0 | Q39: =3*N39+O39 -> 0
A40: J | B40: ='Group Matches'!D22 -> Austria | C40: ='Group Matches'!E22 -> Jordan | D40: =IF(ISNUMBER('Group Matches'!F22),'Group Matches'!F22,0) -> 1 | E40: =IF(ISNUMBER('Group Matches'!G22),'Group Matches'!G22,0) -> 0 | F40: =IF(AND(ISNUMBER('Group Matches'!F22),ISNUMBER('Group Matches'!G22)),1,0) -> 1 | G40: =IF(AND(F40=1,D40>E40),1,0) -> 1 | H40: =IF(AND(F40=1,D40=E40),1,0) -> 0 | I40: =IF(AND(F40=1,D40<E40),1,0) -> 0 | J40: =3*G40+H40 -> 3 | K40: =IF(ISNUMBER('Group Matches'!J22),'Group Matches'!J22,0) -> 0 | L40: =IF(ISNUMBER('Group Matches'!K22),'Group Matches'!K22,0) -> 0 | M40: =IF(AND(ISNUMBER('Group Matches'!J22),ISNUMBER('Group Matches'!K22)),1,0) -> 0 | N40: =IF(AND(M40=1,K40>L40),1,0) -> 0 | O40: =IF(AND(M40=1,K40=L40),1,0) -> 0 | P40: =IF(AND(M40=1,K40<L40),1,0) -> 0 | Q40: =3*N40+O40 -> 0
...

Sheet Standings
A1: GROUP STANDINGS — Ex Ante (predicted) vs Ex Post (actual). Use 'Nudge' (blue) only to break true ties.
A2: Grp | B2: Team | C2: Pld | D2: W | E2: D | F2: L | G2: GF | H2: GA | I2: GD | J2: Pts | K2: Nudge | L2: Key | M2: Rk | N2: Pos | P2: Pld | Q2: W | R2: D | S2: L | T2: GF | U2: GA | V2: GD | W2: Pts | X2: Nudge | Y2: Key | Z2: Rk | AA2: Pos
A3: A | B3: Mexico | C3: =SUMIFS(ENG_Long!$F$2:$F$145,ENG_Long!$B$2:$B$145,$B3) -> 3 | D3: =SUMIFS(ENG_Long!$G$2:$G$145,ENG_Long!$B$2:$B$145,$B3) -> 2 | E3: =SUMIFS(ENG_Long!$H$2:$H$145,ENG_Long!$B$2:$B$145,$B3) -> 0 | F3: =SUMIFS(ENG_Long!$I$2:$I$145,ENG_Long!$B$2:$B$145,$B3) -> 1 | G3: =SUMIFS(ENG_Long!$D$2:$D$145,ENG_Long!$B$2:$B$145,$B3) -> 3 | H3: =SUMIFS(ENG_Long!$E$2:$E$145,ENG_Long!$B$2:$B$145,$B3) -> 2 | I3: =G3-H3 -> 1 | J3: =SUMIFS(ENG_Long!$J$2:$J$145,ENG_Long!$B$2:$B$145,$B3) -> 6 | K3: 0 | L3: =J3*1000000+(I3+100)*1000+G3*10+K3*0.1+0.004 -> 6101030 | M3: =RANK(L3,$L$3:$L$6,0) -> 2 | N3: =CHOOSE(M3,"1st","2nd","3rd","4th") -> 2nd | P3: =SUMIFS(ENG_Long!$M$2:$M$145,ENG_Long!$B$2:$B$145,$B3) -> 1 | Q3: =SUMIFS(ENG_Long!$N$2:$N$145,ENG_Long!$B$2:$B$145,$B3) -> 1 | R3: =SUMIFS(ENG_Long!$O$2:$O$145,ENG_Long!$B$2:$B$145,$B3) -> 0 | S3: =SUMIFS(ENG_Long!$P$2:$P$145,ENG_Long!$B$2:$B$145,$B3) -> 0 | T3: =SUMIFS(ENG_Long!$K$2:$K$145,ENG_Long!$B$2:$B$145,$B3) -> 2 | U3: =SUMIFS(ENG_Long!$L$2:$L$145,ENG_Long!$B$2:$B$145,$B3) -> 0 | V3: =T3-U3 -> 2 | W3: =SUMIFS(ENG_Long!$Q$2:$Q$145,ENG_Long!$B$2:$B$145,$B3) -> 3 | X3: 0 | Y3: =W3*1000000+(V3+100)*1000+T3*10+X3*0.1+0.004 -> 3102020 | Z3: =RANK(Y3,$Y$3:$Y$6,0) -> 1 | AA3: =CHOOSE(Z3,"1st","2nd","3rd","4th") -> 1st
A4: A | B4: South Korea | C4: =SUMIFS(ENG_Long!$F$2:$F$145,ENG_Long!$B$2:$B$145,$B4) -> 3 | D4: =SUMIFS(ENG_Long!$G$2:$G$145,ENG_Long!$B$2:$B$145,$B4) -> 3 | E4: =SUMIFS(ENG_Long!$H$2:$H$145,ENG_Long!$B$2:$B$145,$B4) -> 0 | F4: =SUMIFS(ENG_Long!$I$2:$I$145,ENG_Long!$B$2:$B$145,$B4) -> 0 | G4: =SUMIFS(ENG_Long!$D$2:$D$145,ENG_Long!$B$2:$B$145,$B4) -> 4 | H4: =SUMIFS(ENG_Long!$E$2:$E$145,ENG_Long!$B$2:$B$145,$B4) -> 0 | I4: =G4-H4 -> 4 | J4: =SUMIFS(ENG_Long!$J$2:$J$145,ENG_Long!$B$2:$B$145,$B4) -> 9 | K4: 0 | L4: =J4*1000000+(I4+100)*1000+G4*10+K4*0.1+0.003 -> 9104040 | M4: =RANK(L4,$L$3:$L$6,0) -> 1 | N4: =CHOOSE(M4,"1st","2nd","3rd","4th") -> 1st | P4: =SUMIFS(ENG_Long!$M$2:$M$145,ENG_Long!$B$2:$B$145,$B4) -> 1 | Q4: =SUMIFS(ENG_Long!$N$2:$N$145,ENG_Long!$B$2:$B$145,$B4) -> 1 | R4: =SUMIFS(ENG_Long!$O$2:$O$145,ENG_Long!$B$2:$B$145,$B4) -> 0 | S4: =SUMIFS(ENG_Long!$P$2:$P$145,ENG_Long!$B$2:$B$145,$B4) -> 0 | T4: =SUMIFS(ENG_Long!$K$2:$K$145,ENG_Long!$B$2:$B$145,$B4) -> 2 | U4: =SUMIFS(ENG_Long!$L$2:$L$145,ENG_Long!$B$2:$B$145,$B4) -> 1 | V4: =T4-U4 -> 1 | W4: =SUMIFS(ENG_Long!$Q$2:$Q$145,ENG_Long!$B$2:$B$145,$B4) -> 3 | X4: 0 | Y4: =W4*1000000+(V4+100)*1000+T4*10+X4*0.1+0.003 -> 3101020 | Z4: =RANK(Y4,$Y$3:$Y$6,0) -> 2 | AA4: =CHOOSE(Z4,"1st","2nd","3rd","4th") -> 2nd
A5: A | B5: South Africa | C5: =SUMIFS(ENG_Long!$F$2:$F$145,ENG_Long!$B$2:$B$145,$B5) -> 3 | D5: =SUMIFS(ENG_Long!$G$2:$G$145,ENG_Long!$B$2:$B$145,$B5) -> 0 | E5: =SUMIFS(ENG_Long!$H$2:$H$145,ENG_Long!$B$2:$B$145,$B5) -> 0 | F5: =SUMIFS(ENG_Long!$I$2:$I$145,ENG_Long!$B$2:$B$145,$B5) -> 3 | G5: =SUMIFS(ENG_Long!$D$2:$D$145,ENG_Long!$B$2:$B$145,$B5) -> 0 | H5: =SUMIFS(ENG_Long!$E$2:$E$145,ENG_Long!$B$2:$B$145,$B5) -> 5 | I5: =G5-H5 -> -5 | J5: =SUMIFS(ENG_Long!$J$2:$J$145,ENG_Long!$B$2:$B$145,$B5) -> 0 | K5: 0 | L5: =J5*1000000+(I5+100)*1000+G5*10+K5*0.1+0.002 -> 95000.002 | M5: =RANK(L5,$L$3:$L$6,0) -> 4 | N5: =CHOOSE(M5,"1st","2nd","3rd","4th") -> 4th | P5: =SUMIFS(ENG_Long!$M$2:$M$145,ENG_Long!$B$2:$B$145,$B5) -> 1 | Q5: =SUMIFS(ENG_Long!$N$2:$N$145,ENG_Long!$B$2:$B$145,$B5) -> 0 | R5: =SUMIFS(ENG_Long!$O$2:$O$145,ENG_Long!$B$2:$B$145,$B5) -> 0 | S5: =SUMIFS(ENG_Long!$P$2:$P$145,ENG_Long!$B$2:$B$145,$B5) -> 1 | T5: =SUMIFS(ENG_Long!$K$2:$K$145,ENG_Long!$B$2:$B$145,$B5) -> 0 | U5: =SUMIFS(ENG_Long!$L$2:$L$145,ENG_Long!$B$2:$B$145,$B5) -> 2 | V5: =T5-U5 -> -2 | W5: =SUMIFS(ENG_Long!$Q$2:$Q$145,ENG_Long!$B$2:$B$145,$B5) -> 0 | X5: 0 | Y5: =W5*1000000+(V5+100)*1000+T5*10+X5*0.1+0.002 -> 98000.002 | Z5: =RANK(Y5,$Y$3:$Y$6,0) -> 4 | AA5: =CHOOSE(Z5,"1st","2nd","3rd","4th") -> 4th
A6: A | B6: Czechia | C6: =SUMIFS(ENG_Long!$F$2:$F$145,ENG_Long!$B$2:$B$145,$B6) -> 3 | D6: =SUMIFS(ENG_Long!$G$2:$G$145,ENG_Long!$B$2:$B$145,$B6) -> 1 | E6: =SUMIFS(ENG_Long!$H$2:$H$145,ENG_Long!$B$2:$B$145,$B6) -> 0 | F6: =SUMIFS(ENG_Long!$I$2:$I$145,ENG_Long!$B$2:$B$145,$B6) -> 2 | G6: =SUMIFS(ENG_Long!$D$2:$D$145,ENG_Long!$B$2:$B$145,$B6) -> 3 | H6: =SUMIFS(ENG_Long!$E$2:$E$145,ENG_Long!$B$2:$B$145,$B6) -> 3 | I6: =G6-H6 -> 0 | J6: =SUMIFS(ENG_Long!$J$2:$J$145,ENG_Long!$B$2:$B$145,$B6) -> 3 | K6: 0 | L6: =J6*1000000+(I6+100)*1000+G6*10+K6*0.1+0.001 -> 3100030 | M6: =RANK(L6,$L$3:$L$6,0) -> 3 | N6: =CHOOSE(M6,"1st","2nd","3rd","4th") -> 3rd | P6: =SUMIFS(ENG_Long!$M$2:$M$145,ENG_Long!$B$2:$B$145,$B6) -> 1 | Q6: =SUMIFS(ENG_Long!$N$2:$N$145,ENG_Long!$B$2:$B$145,$B6) -> 0 | R6: =SUMIFS(ENG_Long!$O$2:$O$145,ENG_Long!$B$2:$B$145,$B6) -> 0 | S6: =SUMIFS(ENG_Long!$P$2:$P$145,ENG_Long!$B$2:$B$145,$B6) -> 1 | T6: =SUMIFS(ENG_Long!$K$2:$K$145,ENG_Long!$B$2:$B$145,$B6) -> 1 | U6: =SUMIFS(ENG_Long!$L$2:$L$145,ENG_Long!$B$2:$B$145,$B6) -> 2 | V6: =T6-U6 -> -1 | W6: =SUMIFS(ENG_Long!$Q$2:$Q$145,ENG_Long!$B$2:$B$145,$B6) -> 0 | X6: 0 | Y6: =W6*1000000+(V6+100)*1000+T6*10+X6*0.1+0.001 -> 99010.001 | Z6: =RANK(Y6,$Y$3:$Y$6,0) -> 3 | AA6: =CHOOSE(Z6,"1st","2nd","3rd","4th") -> 3rd
A7: B | B7: Canada | C7: =SUMIFS(ENG_Long!$F$2:$F$145,ENG_Long!$B$2:$B$145,$B7) -> 3 | D7: =SUMIFS(ENG_Long!$G$2:$G$145,ENG_Long!$B$2:$B$145,$B7) -> 1 | E7: =SUMIFS(ENG_Long!$H$2:$H$145,ENG_Long!$B$2:$B$145,$B7) -> 1 | F7: =SUMIFS(ENG_Long!$I$2:$I$145,ENG_Long!$B$2:$B$145,$B7) -> 1 | G7: =SUMIFS(ENG_Long!$D$2:$D$145,ENG_Long!$B$2:$B$145,$B7) -> 3 | H7: =SUMIFS(ENG_Long!$E$2:$E$145,ENG_Long!$B$2:$B$145,$B7) -> 2 | I7: =G7-H7 -> 1 | J7: =SUMIFS(ENG_Long!$J$2:$J$145,ENG_Long!$B$2:$B$145,$B7) -> 4 | K7: 0 | L7: =J7*1000000+(I7+100)*1000+G7*10+K7*0.1+0.004 -> 4101030 | M7: =RANK(L7,$L$7:$L$10,0) -> 3 | N7: =CHOOSE(M7,"1st","2nd","3rd","4th") -> 3rd | P7: =SUMIFS(ENG_Long!$M$2:$M$145,ENG_Long!$B$2:$B$145,$B7) -> 1 | Q7: =SUMIFS(ENG_Long!$N$2:$N$145,ENG_Long!$B$2:$B$145,$B7) -> 0 | R7: =SUMIFS(ENG_Long!$O$2:$O$145,ENG_Long!$B$2:$B$145,$B7) -> 1 | S7: =SUMIFS(ENG_Long!$P$2:$P$145,ENG_Long!$B$2:$B$145,$B7) -> 0 | T7: =SUMIFS(ENG_Long!$K$2:$K$145,ENG_Long!$B$2:$B$145,$B7) -> 1 | U7: =SUMIFS(ENG_Long!$L$2:$L$145,ENG_Long!$B$2:$B$145,$B7) -> 1 | V7: =T7-U7 -> 0 | W7: =SUMIFS(ENG_Long!$Q$2:$Q$145,ENG_Long!$B$2:$B$145,$B7) -> 1 | X7: 0 | Y7: =W7*1000000+(V7+100)*1000+T7*10+X7*0.1+0.004 -> 1100010 | Z7: =RANK(Y7,$Y$7:$Y$10,0) -> 1 | AA7: =CHOOSE(Z7,"1st","2nd","3rd","4th") -> 1st
A8: B | B8: Switzerland | C8: =SUMIFS(ENG_Long!$F$2:$F$145,ENG_Long!$B$2:$B$145,$B8) -> 3 | D8: =SUMIFS(ENG_Long!$G$2:$G$145,ENG_Long!$B$2:$B$145,$B8) -> 1 | E8: =SUMIFS(ENG_Long!$H$2:$H$145,ENG_Long!$B$2:$B$145,$B8) -> 2 | F8: =SUMIFS(ENG_Long!$I$2:$I$145,ENG_Long!$B$2:$B$145,$B8) -> 0 | G8: =SUMIFS(ENG_Long!$D$2:$D$145,ENG_Long!$B$2:$B$145,$B8) -> 4 | H8: =SUMIFS(ENG_Long!$E$2:$E$145,ENG_Long!$B$2:$B$145,$B8) -> 2 | I8: =G8-H8 -> 2 | J8: =SUMIFS(ENG_Long!$J$2:$J$145,ENG_Long!$B$2:$B$145,$B8) -> 5 | K8: 0 | L8: =J8*1000000+(I8+100)*1000+G8*10+K8*0.1+0.003 -> 5102040 | M8: =RANK(L8,$L$7:$L$10,0) -> 2 | N8: =CHOOSE(M8,"1st","2nd","3rd","4th") -> 2nd | P8: =SUMIFS(ENG_Long!$M$2:$M$145,ENG_Long!$B$2:$B$145,$B8) -> 1 | Q8: =SUMIFS(ENG_Long!$N$2:$N$145,ENG_Long!$B$2:$B$145,$B8) -> 0 | R8: =SUMIFS(ENG_Long!$O$2:$O$145,ENG_Long!$B$2:$B$145,$B8) -> 1 | S8: =SUMIFS(ENG_Long!$P$2:$P$145,ENG_Long!$B$2:$B$145,$B8) -> 0 | T8: =SUMIFS(ENG_Long!$K$2:$K$145,ENG_Long!$B$2:$B$145,$B8) -> 1 | U8: =SUMIFS(ENG_Long!$L$2:$L$145,ENG_Long!$B$2:$B$145,$B8) -> 1 | V8: =T8-U8 -> 0 | W8: =SUMIFS(ENG_Long!$Q$2:$Q$145,ENG_Long!$B$2:$B$145,$B8) -> 1 | X8: 0 | Y8: =W8*1000000+(V8+100)*1000+T8*10+X8*0.1+0.003 -> 1100010 | Z8: =RANK(Y8,$Y$7:$Y$10,0) -> 2 | AA8: =CHOOSE(Z8,"1st","2nd","3rd","4th") -> 2nd
A9: B | B9: Qatar | C9: =SUMIFS(ENG_Long!$F$2:$F$145,ENG_Long!$B$2:$B$145,$B9) -> 3 | D9: =SUMIFS(ENG_Long!$G$2:$G$145,ENG_Long!$B$2:$B$145,$B9) -> 0 | E9: =SUMIFS(ENG_Long!$H$2:$H$145,ENG_Long!$B$2:$B$145,$B9) -> 0 | F9: =SUMIFS(ENG_Long!$I$2:$I$145,ENG_Long!$B$2:$B$145,$B9) -> 3 | G9: =SUMIFS(ENG_Long!$D$2:$D$145,ENG_Long!$B$2:$B$145,$B9) -> 0 | H9: =SUMIFS(ENG_Long!$E$2:$E$145,ENG_Long!$B$2:$B$145,$B9) -> 6 | I9: =G9-H9 -> -6 | J9: =SUMIFS(ENG_Long!$J$2:$J$145,ENG_Long!$B$2:$B$145,$B9) -> 0 | K9: 0 | L9: =J9*1000000+(I9+100)*1000+G9*10+K9*0.1+0.002 -> 94000.002 | M9: =RANK(L9,$L$7:$L$10,0) -> 4 | N9: =CHOOSE(M9,"1st","2nd","3rd","4th") -> 4th | P9: =SUMIFS(ENG_Long!$M$2:$M$145,ENG_Long!$B$2:$B$145,$B9) -> 1 | Q9: =SUMIFS(ENG_Long!$N$2:$N$145,ENG_Long!$B$2:$B$145,$B9) -> 0 | R9: =SUMIFS(ENG_Long!$O$2:$O$145,ENG_Long!$B$2:$B$145,$B9) -> 1 | S9: =SUMIFS(ENG_Long!$P$2:$P$145,ENG_Long!$B$2:$B$145,$B9) -> 0 | T9: =SUMIFS(ENG_Long!$K$2:$K$145,ENG_Long!$B$2:$B$145,$B9) -> 1 | U9: =SUMIFS(ENG_Long!$L$2:$L$145,ENG_Long!$B$2:$B$145,$B9) -> 1 | V9: =T9-U9 -> 0 | W9: =SUMIFS(ENG_Long!$Q$2:$Q$145,ENG_Long!$B$2:$B$145,$B9) -> 1 | X9: 0 | Y9: =W9*1000000+(V9+100)*1000+T9*10+X9*0.1+0.002 -> 1100010 | Z9: =RANK(Y9,$Y$7:$Y$10,0) -> 3 | AA9: =CHOOSE(Z9,"1st","2nd","3rd","4th") -> 3rd
A10: B | B10: Bosnia & Herzegovina | C10: =SUMIFS(ENG_Long!$F$2:$F$145,ENG_Long!$B$2:$B$145,$B10) -> 3 | D10: =SUMIFS(ENG_Long!$G$2:$G$145,ENG_Long!$B$2:$B$145,$B10) -> 2 | E10: =SUMIFS(ENG_Long!$H$2:$H$145,ENG_Long!$B$2:$B$145,$B10) -> 1 | F10: =SUMIFS(ENG_Long!$I$2:$I$145,ENG_Long!$B$2:$B$145,$B10) -> 0 | G10: =SUMIFS(ENG_Long!$D$2:$D$145,ENG_Long!$B$2:$B$145,$B10) -> 4 | H10: =SUMIFS(ENG_Long!$E$2:$E$145,ENG_Long!$B$2:$B$145,$B10) -> 1 | I10: =G10-H10 -> 3 | J10: =SUMIFS(ENG_Long!$J$2:$J$145,ENG_Long!$B$2:$B$145,$B10) -> 7 | K10: 0 | L10: =J10*1000000+(I10+100)*1000+G10*10+K10*0.1+0.001 -> 7103040 | M10: =RANK(L10,$L$7:$L$10,0) -> 1 | N10: =CHOOSE(M10,"1st","2nd","3rd","4th") -> 1st | P10: =SUMIFS(ENG_Long!$M$2:$M$145,ENG_Long!$B$2:$B$145,$B10) -> 1 | Q10: =SUMIFS(ENG_Long!$N$2:$N$145,ENG_Long!$B$2:$B$145,$B10) -> 0 | R10: =SUMIFS(ENG_Long!$O$2:$O$145,ENG_Long!$B$2:$B$145,$B10) -> 1 | S10: =SUMIFS(ENG_Long!$P$2:$P$145,ENG_Long!$B$2:$B$145,$B10) -> 0 | T10: =SUMIFS(ENG_Long!$K$2:$K$145,ENG_Long!$B$2:$B$145,$B10) -> 1 | U10: =SUMIFS(ENG_Long!$L$2:$L$145,ENG_Long!$B$2:$B$145,$B10) -> 1 | V10: =T10-U10 -> 0 | W10: =SUMIFS(ENG_Long!$Q$2:$Q$145,ENG_Long!$B$2:$B$145,$B10) -> 1 | X10: 0 | Y10: =W10*1000000+(V10+100)*1000+T10*10+X10*0.1+0.001 -> 1100010 | Z10: =RANK(Y10,$Y$7:$Y$10,0) -> 4 | AA10: =CHOOSE(Z10,"1st","2nd","3rd","4th") -> 4th
